Workbook

Sheet BASE 
A1: CONDIÇÃO
A2: N.A. | B2: Desligados, transferidos, afastados.
A3: APROVADO | B3: Treinamento de formação realizado ou reciclado, com aprovação mínima e dentro do prazo de validade
A4: RECICLADO | B4: Treinamento já reciclado. Linha de histórico
A5: SEM REGISTRO | B5: Nunca fez o treinamento
A6: REPROVADO | B6: Treinamento reciclado porém não atigingiu pontuação mínima para aprovação na avaliação. Necessário repescagem.
A9: STATUS
A10: N.A. | B10: Desligados, transferidos, afastados.
A11: NO PRAZO | B11: Treinamento de formação realizado ou reciclado, com aprovação mínima e dentro do prazo de validade
A12: VENCIDO | B12: Treinamento fora do prazo de validade.
A13: HISTORICO | B13: Treinamento já reciclado. Linha de histórico
A14: SEM REGISTRO | B14: Nunca fez o treinamento
A15: REPROVADO | B15: Treinamento reciclado porém não atigingiu pontuação mínima para aprovação na avaliação. Necessário repescagem.

Sheet CADASTRO
A1: NOME | B1: TURNO COMP | C1: TURNO | D1: COORDENADOR | E1: FUNÇÃO | F1: STATUS | G1: ÁREA | H1: IDFIXO
A2: REDIVALDO BARBOSA | B2: 0 - ADM - BH 6X1/5X2 08:0 | C2: 0 | D2: GIOVANNA CRIPPA BIFFARATTE | E2: ANALISTA PROCESSOS | F2: TRANSFERIDO | G2: MELHORIA CONTINUA | H2: 1
A3: WEVERTON MEDEIRO | B3: 2º turno - 6x1 - 14:00 ás | C3: 2 | D3: MICHELLE APARECIDA FARIA | E3: OPERADOR INDUSTRIAL I | F3: DESLIGADO | G3: FABRIMA | H3: 2
A4: YAN HENRIQUE COSTA | B4: 3º turno - 6x1 - 22:00 ás | C4: 3 | D4: HIAGO DA SILVA DANTAS | E4: AUXILIAR INDUSTRIAL | F4: DESLIGADO | G4: FABRIMA | H4: 3
A5: YUAN JOSE DE OLIVEIRA | B5: HIRE NOW | C5: H | D5: RICARDO BAPTISTA NISHIDA | E5: AUXILIAR INDUSTRIAL | F5: DESLIGADO | G5: FABRIMA | H5: 4
A6: WESLEY MARCELINO DE JESUS | B6: 1º turno - 6x1 - 06:00 ás | C6: 1 | D6: FABIO ASSIS DE OLIVEIRA | E6: OPERADOR LOGISTICO I | F6: DESLIGADO | G6: LOGÍSTICA | H6: 5
A7: WARLEY DA CUNHA SANTANA | B7: 2º turno - 6x1 - 14:00 ás | C7: 2 | D7: FABIO ASSIS DE OLIVEIRA | E7: OPERADOR LOGISTICO I | F7: DESLIGADO | G7: LOGÍSTICA | H7: 6
A8: VIVIANE FILOMENA DA SILVA | B8: 3º turno - 6x1 - 22:00 ás | C8: 3 | D8: HIAGO DA SILVA DANTAS | E8: AUXILIAR INDUSTRIAL | F8: DESLIGADO | G8: FABRIMA | H8: 7
A9: VITOR LIMA DE OLIVEIRA | B9: 0 - ADM - SEG/SEX - 13:30 | C9: 0 | D9: ELIEZER SILVA | E9: APRENDIZ | F9: DESLIGADO | G9: MANUTENÇÃO ADM | H9: 8
A10: VINICIUS CESAR DE OLIVEIRA BATISTA | B10: 3º turno - 6x1 - 22:00 ás | C10: 3 | D10: HIAGO DA SILVA DANTAS | E10: OPERADOR INDUSTRIAL II | F10: DESLIGADO | G10: PKD | H10: 9
A11: VERENA APARECIDA RODRIGUES SILVA | B11: 0 - ADM - SEG / SEX 08:30 | C11: 0 | D11: GIOVANNA CRIPPA BIFFARATTE | E11: ESTAGIARIO | F11: DESLIGADO | G11: MELHORIA CONTINUA | H11: 10
A12: VALDECI JUSTINO SIMOES | B12: 3º turno - 6x1 - 22:00 ás | C12: 3 | D12: CAIO GUILHERME SALES FERREIRA | E12: OPERADOR INDUSTRIAL II | F12: DESLIGADO | G12: CAFÉ VERDE | H12: 11
A13: TIAGO DELFINO DE OLIVEIRA | B13: 1º turno - 6x1 - 06:00 ás | C13: 1 | D13: HIAGO DA SILVA DANTAS | E13: OPERADOR INDUSTRIAL I | F13: DESLIGADO | G13: FABRIMA | H13: 12
... A329: GLAUCIURI RODRIGUES DE SENA | B329: HIRE NOW | C329: H | D329: LEONARDO ANTONIO FRANCELINO JUNIOR | E329: AUXILIAR INDUSTRIAL | F329: ATIVO | G329: FABRIMA | H329: 353

Sheet NR05
A1: ORIGEM | B1: FORNECEDOR | C1: INSTRUTOR | D1: TREINAMENTO | E1: NOME | F1: CARGO | G1: TREINADO EM | H1: VALIDADE | I1: STATUS | J1: VENCE EM | K1: CARGA HORARIA | L1: CONDIÇÃO | M1: SITUAÇÃO
A2: EXTERNO | B2: MERITUS | C2: FELICIO MATOS | D2: NR 05 - CIPA | E2: ALEX SANDRO ALVES TEIXEIRA | F2: =VLOOKUP(CIPA[[#This Row],[NOME]],'CADASTRO'!A:K,5,0) -> OPERADOR INDUSTRIAL II | G2: 45629 | H2: 730 | I2: =IF(CIPA[[#This Row],[SITUAÇÃO]]="ATIVO", IF(CIPA[[#This Row],[CONDIÇÃO]]="N.A.", "N.A.", IF(CIPA[[#This Row],[CONDIÇÃO]]="REPROVADO", "REPROVADO", IF(CIPA[[#This Row],[CONDIÇÃO]]="RECICLADO", "HISTORICO", IF(CIPA[[#This Row],[CONDIÇÃO]]="SEM REGISTRO", "SEM REGISTRO", IF(G326="01/01/1900", "SEM REGISTRO", IF((G2+H2)>TODAY(), "NO PRAZO", "VENCIDO" ) ) ) ) ) ),"N.A.") -> HISTORICO | J2: =CIPA[[#This Row],[TREINADO EM]]+CIPA[[#This Row],[VALIDADE]] -> 46359 | K2: 16 | L2: RECICLADO | M2: =VLOOKUP(CIPA[[#This Row],[NOME]],'CADASTRO'!A:K,6,0) -> ATIVO
A3: EXTERNO | B3: MERITUS | C3: FELICIO MATOS | D3: NR 05 - CIPA | E3: ALEXANDRE BATISTA DE OLIVEIRA | F3: =VLOOKUP(CIPA[[#This Row],[NOME]],'CADASTRO'!A:K,5,0) -> TECNICO MECANICO III | G3: 46001 | H3: 730 | I3: =IF(CIPA[[#This Row],[SITUAÇÃO]]="ATIVO", IF(CIPA[[#This Row],[CONDIÇÃO]]="N.A.", "N.A.", IF(CIPA[[#This Row],[CONDIÇÃO]]="REPROVADO", "REPROVADO", IF(CIPA[[#This Row],[CONDIÇÃO]]="RECICLADO", "HISTORICO", IF(CIPA[[#This Row],[CONDIÇÃO]]="SEM REGISTRO", "SEM REGISTRO", IF(G327="01/01/1900", "SEM REGISTRO", IF((G3+H3)>TODAY(), "NO PRAZO", "VENCIDO" ) ) ) ) ) ),"N.A.") -> NO PRAZO | J3: =CIPA[[#This Row],[TREINADO EM]]+CIPA[[#This Row],[VALIDADE]] -> 46731 | K3: 16 | L3: APROVADO | M3: =VLOOKUP(CIPA[[#This Row],[NOME]],'CADASTRO'!A:K,6,0) -> ATIVO
A4: EXTERNO | B4: EXXCELENCIA | C4: SAYMON | D4: NR 05 - CIPA | E4: ALEXANDRE DE ASSIS DA COSTA | F4: =VLOOKUP(CIPA[[#This Row],[NOME]],'CADASTRO'!A:K,5,0) -> TECNICO MECANICO II | G4: 45426 | H4: 730 | I4: =IF(CIPA[[#This Row],[SITUAÇÃO]]="ATIVO", IF(CIPA[[#This Row],[CONDIÇÃO]]="N.A.", "N.A.", IF(CIPA[[#This Row],[CONDIÇÃO]]="REPROVADO", "REPROVADO", IF(CIPA[[#This Row],[CONDIÇÃO]]="RECICLADO", "HISTORICO", IF(CIPA[[#This Row],[CONDIÇÃO]]="SEM REGISTRO", "SEM REGISTRO", IF(G328="01/01/1900", "SEM REGISTRO", IF((G4+H4)>TODAY(), "NO PRAZO", "VENCIDO" ) ) ) ) ) ),"N.A.") -> N.A. | J4: =CIPA[[#This Row],[TREINADO EM]]+CIPA[[#This Row],[VALIDADE]] -> 46156 | K4: 16 | L4: N.A. | M4: =VLOOKUP(CIPA[[#This Row],[NOME]],'CADASTRO'!A:K,6,0) -> ATIVO
A5: EXTERNO | B5: MERITUS | C5: FELICIO MATOS | D5: NR 05 - CIPA | E5: ALINE FERNANDES | F5: =VLOOKUP(CIPA[[#This Row],[NOME]],'CADASTRO'!A:K,5,0) -> ASSISTENTE ADMINISTRATIVO | G5: 46001 | H5: 730 | I5: =IF(CIPA[[#This Row],[SITUAÇÃO]]="ATIVO", IF(CIPA[[#This Row],[CONDIÇÃO]]="N.A.", "N.A.", IF(CIPA[[#This Row],[CONDIÇÃO]]="REPROVADO", "REPROVADO", IF(CIPA[[#This Row],[CONDIÇÃO]]="RECICLADO", "HISTORICO", IF(CIPA[[#This Row],[CONDIÇÃO]]="SEM REGISTRO", "SEM REGISTRO", IF(G329="01/01/1900", "SEM REGISTRO", IF((G5+H5)>TODAY(), "NO PRAZO", "VENCIDO" ) ) ) ) ) ),"N.A.") -> NO PRAZO | J5: =CIPA[[#This Row],[TREINADO EM]]+CIPA[[#This Row],[VALIDADE]] -> 46731 | K5: 16 | L5: APROVADO | M5: =VLOOKUP(CIPA[[#This Row],[NOME]],'CADASTRO'!A:K,6,0) -> ATIVO
A6: EXTERNO | B6: EXXCELENCIA | C6: VINICIUS FERREIRA | D6: NR 05 - CIPA | E6: ANDRE LUIS MENDES COSTA | F6: =VLOOKUP(CIPA[[#This Row],[NOME]],'CADASTRO'!A:K,5,0) -> Analista PCM PL | G6: 45267 | H6: 730 | I6: =IF(CIPA[[#This Row],[SITUAÇÃO]]="ATIVO", IF(CIPA[[#This Row],[CONDIÇÃO]]="N.A.", "N.A.", IF(CIPA[[#This Row],[CONDIÇÃO]]="REPROVADO", "REPROVADO", IF(CIPA[[#This Row],[CONDIÇÃO]]="RECICLADO", "HISTORICO", IF(CIPA[[#This Row],[CONDIÇÃO]]="SEM REGISTRO", "SEM REGISTRO", IF(G330="01/01/1900", "SEM REGISTRO", IF((G6+H6)>TODAY(), "NO PRAZO", "VENCIDO" ) ) ) ) ) ),"N.A.") -> N.A. | J6: =CIPA[[#This Row],[TREINADO EM]]+CIPA[[#This Row],[VALIDADE]] -> 45997 | K6: 16 | L6: N.A. | M6: =VLOOKUP(CIPA[[#This Row],[NOME]],'CADASTRO'!A:K,6,0) -> ATIVO
A7: EXTERNO | B7: EXXCELENCIA | C7: VINICIUS FERREIRA | D7: NR 05 - CIPA | E7: ARTHUR FIGUEIREDO DA SILVA | F7: =VLOOKUP(CIPA[[#This Row],[NOME]],'CADASTRO'!A:K,5,0) -> TECNICO MECANICO II | G7: 44545 | H7: 730 | I7: =IF(CIPA[[#This Row],[SITUAÇÃO]]="ATIVO", IF(CIPA[[#This Row],[CONDIÇÃO]]="N.A.", "N.A.", IF(CIPA[[#This Row],[CONDIÇÃO]]="REPROVADO", "REPROVADO", IF(CIPA[[#This Row],[CONDIÇÃO]]="RECICLADO", "HISTORICO", IF(CIPA[[#This Row],[CONDIÇÃO]]="SEM REGISTRO", "SEM REGISTRO", IF(G331="01/01/1900", "SEM REGISTRO", IF((G7+H7)>TODAY(), "NO PRAZO", "VENCIDO" ) ) ) ) ) ),"N.A.") -> N.A. | J7: =CIPA[[#This Row],[TREINADO EM]]+CIPA[[#This Row],[VALIDADE]] -> 45275 | K7: 20 | L7: N.A. | M7: =VLOOKUP(CIPA[[#This Row],[NOME]],'CADASTRO'!A:K,6,0) -> ATIVO
A8: EXTERNO | B8: EXXCELENCIA | C8: VINICIUS FERREIRA | D8: NR 05 - CIPA | E8: ARTHUR FIGUEIREDO DA SILVA | F8: =VLOOKUP(CIPA[[#This Row],[NOME]],'CADASTRO'!A:K,5,0) -> TECNICO MECANICO II | G8: 44900 | H8: 730 | I8: =IF(CIPA[[#This Row],[SITUAÇÃO]]="ATIVO", IF(CIPA[[#This Row],[CONDIÇÃO]]="N.A.", "N.A.", IF(CIPA[[#This Row],[CONDIÇÃO]]="REPROVADO", "REPROVADO", IF(CIPA[[#This Row],[CONDIÇÃO]]="RECICLADO", "HISTORICO", IF(CIPA[[#This Row],[CONDIÇÃO]]="SEM REGISTRO", "SEM REGISTRO", IF(G332="01/01/1900", "SEM REGISTRO", IF((G8+H8)>TODAY(), "NO PRAZO", "VENCIDO" ) ) ) ) ) ),"N.A.") -> N.A. | J8: =CIPA[[#This Row],[TREINADO EM]]+CIPA[[#This Row],[VALIDADE]] -> 45630 | K8: 20 | L8: N.A. | M8: =VLOOKUP(CIPA[[#This Row],[NOME]],'CADASTRO'!A:K,6,0) -> ATIVO
A9: EXTERNO | B9: EXXCELENCIA | C9: VINICIUS FERREIRA | D9: NR 05 - CIPA | E9: ARTHUR FIGUEIREDO DA SILVA | F9: =VLOOKUP(CIPA[[#This Row],[NOME]],'CADASTRO'!A:K,5,0) -> TECNICO MECANICO II | G9: 45267 | H9: 730 | I9: =IF(CIPA[[#This Row],[SITUAÇÃO]]="ATIVO", IF(CIPA[[#This Row],[CONDIÇÃO]]="N.A.", "N.A.", IF(CIPA[[#This Row],[CONDIÇÃO]]="REPROVADO", "REPROVADO", IF(CIPA[[#This Row],[CONDIÇÃO]]="RECICLADO", "HISTORICO", IF(CIPA[[#This Row],[CONDIÇÃO]]="SEM REGISTRO", "SEM REGISTRO", IF(G333="01/01/1900", "SEM REGISTRO", IF((G9+H9)>TODAY(), "NO PRAZO", "VENCIDO" ) ) ) ) ) ),"N.A.") -> N.A. | J9: =CIPA[[#This Row],[TREINADO EM]]+CIPA[[#This Row],[VALIDADE]] -> 45997 | K9: 16 | L9: N.A. | M9: =VLOOKUP(CIPA[[#This Row],[NOME]],'CADASTRO'!A:K,6,0) -> ATIVO
A10: EXTERNO | B10: MERITUS | C10: FELICIO MATOS | D10: NR 05 - CIPA | E10: BIANCA PIERAZO E SILVA | F10: =VLOOKUP(CIPA[[#This Row],[NOME]],'CADASTRO'!A:K,5,0) -> ASSISTENTE ADMINISTRATIVO | G10: 45629 | H10: 730 | I10: =IF(CIPA[[#This Row],[SITUAÇÃO]]="ATIVO", IF(CIPA[[#This Row],[CONDIÇÃO]]="N.A.", "N.A.", IF(CIPA[[#This Row],[CONDIÇÃO]]="REPROVADO", "REPROVADO", IF(CIPA[[#This Row],[CONDIÇÃO]]="RECICLADO", "HISTORICO", IF(CIPA[[#This Row],[CONDIÇÃO]]="SEM REGISTRO", "SEM REGISTRO", IF(G334="01/01/1900", "SEM REGISTRO", IF((G10+H10)>TODAY(), "NO PRAZO", "VENCIDO" ) ) ) ) ) ),"N.A.") -> N.A. | J10: =CIPA[[#This Row],[TREINADO EM]]+CIPA[[#This Row],[VALIDADE]] -> 46359 | K10: 16 | L10: APROVADO | M10: =VLOOKUP(CIPA[[#This Row],[NOME]],'CADASTRO'!A:K,6,0) -> DESLIGADO
A11: EXTERNO | B11: EXXCELENCIA | C11: VINICIUS FERREIRA | D11: NR 05 - CIPA | E11: BRUNO HENRIQUE HONORIO SILVA | F11: =VLOOKUP(CIPA[[#This Row],[NOME]],'CADASTRO'!A:K,5,0) -> AUXILIAR INDUSTRIAL | G11: 44545 | H11: 730 | I11: =IF(CIPA[[#This Row],[SITUAÇÃO]]="ATIVO", IF(CIPA[[#This Row],[CONDIÇÃO]]="N.A.", "N.A.", IF(CIPA[[#This Row],[CONDIÇÃO]]="REPROVADO", "REPROVADO", IF(CIPA[[#This Row],[CONDIÇÃO]]="RECICLADO", "HISTORICO", IF(CIPA[[#This Row],[CONDIÇÃO]]="SEM REGISTRO", "SEM REGISTRO", IF(G335="01/01/1900", "SEM REGISTRO", IF((G11+H11)>TODAY(), "NO PRAZO", "VENCIDO" ) ) ) ) ) ),"N.A.") -> N.A. | J11: =CIPA[[#This Row],[TREINADO EM]]+CIPA[[#This Row],[VALIDADE]] -> 45275 | K11: 20 | L11: N.A. | M11: =VLOOKUP(CIPA[[#This Row],[NOME]],'CADASTRO'!A:K,6,0) -> DESLIGADO
A12: EXTERNO | B12: MERITUS | C12: FELICIO MATOS | D12: NR 05 - CIPA | E12: CAMILA CRISTINA BASILIO | F12: =VLOOKUP(CIPA[[#This Row],[NOME]],'CADASTRO'!A:K,5,0) -> SUPERVISOR DE OPERAÇÕES | G12: 45629 | H12: 730 | I12: =IF(CIPA[[#This Row],[SITUAÇÃO]]="ATIVO", IF(CIPA[[#This Row],[CONDIÇÃO]]="N.A.", "N.A.", IF(CIPA[[#This Row],[CONDIÇÃO]]="REPROVADO", "REPROVADO", IF(CIPA[[#This Row],[CONDIÇÃO]]="RECICLADO", "HISTORICO", IF(CIPA[[#This Row],[CONDIÇÃO]]="SEM REGISTRO", "SEM REGISTRO", IF(G336="01/01/1900", "SEM REGISTRO", IF((G12+H12)>TODAY(), "NO PRAZO", "VENCIDO" ) ) ) ) ) ),"N.A.") -> HISTORICO | J12: =CIPA[[#This Row],[TREINADO EM]]+CIPA[[#This Row],[VALIDADE]] -> 46359 | K12: 16 | L12: RECICLADO | M12: =VLOOKUP(CIPA[[#This Row],[NOME]],'CADASTRO'!A:K,6,0) -> ATIVO
A13: EXTERNO | B13: MERITUS | C13: FELICIO MATOS | D13: NR 05 - CIPA | E13: CAMILA CRISTINA BASILIO | F13: =VLOOKUP(CIPA[[#This Row],[NOME]],'CADASTRO'!A:K,5,0) -> SUPERVISOR DE OPERAÇÕES | G13: 46001 | H13: 730 | I13: =IF(CIPA[[#This Row],[SITUAÇÃO]]="ATIVO", IF(CIPA[[#This Row],[CONDIÇÃO]]="N.A.", "N.A.", IF(CIPA[[#This Row],[CONDIÇÃO]]="REPROVADO", "REPROVADO", IF(CIPA[[#This Row],[CONDIÇÃO]]="RECICLADO", "HISTORICO", IF(CIPA[[#This Row],[CONDIÇÃO]]="SEM REGISTRO", "SEM REGISTRO", IF(G337="01/01/1900", "SEM REGISTRO", IF((G13+H13)>TODAY(), "NO PRAZO", "VENCIDO" ) ) ) ) ) ),"N.A.") -> NO PRAZO | J13: =CIPA[[#This Row],[TREINADO EM]]+CIPA[[#This Row],[VALIDADE]] -> 46731 | K13: 16 | L13: APROVADO | M13: =VLOOKUP(CIPA[[#This Row],[NOME]],'CADASTRO'!A:K,6,0) -> ATIVO
... A59: EXTERNO | B59: MERITUS | C59: FELICIO MATOS | D59: NR 05 - CIPA | E59: VINICIUS RAMOS DE OLIVEIRA | F59: =VLOOKUP(CIPA[[#This Row],[NOME]],'CADASTRO'!A:K,5,0) -> OPERADOR INDUSTRIAL III | G59: 46001 | H59: 730 | I59: =IF(CIPA[[#This Row],[SITUAÇÃO]]="ATIVO", IF(CIPA[[#This Row],[CONDIÇÃO]]="N.A.", "N.A.", IF(CIPA[[#This Row],[CONDIÇÃO]]="REPROVADO", "REPROVADO", IF(CIPA[[#This Row],[CONDIÇÃO]]="RECICLADO", "HISTORICO", IF(CIPA[[#This Row],[CONDIÇÃO]]="SEM REGISTRO", "SEM REGISTRO", IF(G383="01/01/1900", "SEM REGISTRO", IF((G59+H59)>TODAY(), "NO PRAZO", "VENCIDO" ) ) ) ) ) ),"N.A.") -> NO PRAZO | J59: =CIPA[[#This Row],[TREINADO EM]]+CIPA[[#This Row],[VALIDADE]] -> 46731 | K59: 16 | L59: APROVADO | M59: =VLOOKUP(CIPA[[#This Row],[NOME]],'CADASTRO'!A:K,6,0) -> ATIVO

Sheet NR06 EPI
A1: ORIGEM | B1: FORNECEDOR | C1: INSTRUTOR | D1: TREINAMENTO | E1: NOME | F1: CARGO | G1: TREINADO EM | H1: VALIDADE | I1: STATUS | J1: VENCE EM | K1: CARGA HORARIA | L1: CONDIÇÃO | M1: SITUAÇÃO | N1: LINK | Q1: Algum dado repetido? | S1: =IF(OR(COUNTIFS(E:E,B2,I:I,"NO PRAZO")>1, COUNTIFS(E:E,B2,I:I,"VENCIDO")>1, AND(COUNTIFS(E:E,B2,I:I,"NO PRAZO")>=1, COUNTIFS(E:E,B2,I:I,"VENCIDO")>=1)), "TREINAMENTO NÃO RECEBEU RECICLADO", "OK") -> OK
A2: INTERNO | B2: PIU JDE | C2: GUILHERME DOS REIS OLIVEIRA | D2: NR 06 EPI | E2: ABNER BARROS DE PAIVA | F2: =VLOOKUP(EPI[[#This Row],[NOME]],'CADASTRO'!A:K,5,0) -> OPERADOR INDUSTRIAL I | G2: 46119 | H2: 365 | I2: =IF(EPI[[#This Row],[SITUAÇÃO]]="ATIVO", IF(EPI[[#This Row],[CONDIÇÃO]]="N.A.", "N.A.", IF(EPI[[#This Row],[CONDIÇÃO]]="REPROVADO", "REPROVADO", IF(EPI[[#This Row],[CONDIÇÃO]]="RECICLADO", "HISTORICO", IF(EPI[[#This Row],[CONDIÇÃO]]="SEM REGISTRO", "SEM REGISTRO", IF(G391="01/01/1900", "SEM REGISTRO", IF((G2+H2)>TODAY(), "NO PRAZO", "VENCIDO" ) ) ) ) ) ),"N.A.") -> NO PRAZO | J2: =EPI[[#This Row],[TREINADO EM]]+EPI[[#This Row],[VALIDADE]] -> 46484 | K2: 0.15 | L2: APROVADO | M2: =VLOOKUP(EPI[[#This Row],[NOME]],'CADASTRO'!A:K,6,0) -> ATIVO | N2: EPI 07-04-2026
A3: INTERNO | B3: PIU JDE | C3: GUILHERME DOS REIS OLIVEIRA | D3: NR 06 EPI | E3: ALEX BARBARA | F3: =VLOOKUP(EPI[[#This Row],[NOME]],'CADASTRO'!A:K,5,0) -> TECNICO MECANICO II | G3: 45092 | H3: 365 | I3: =IF(EPI[[#This Row],[SITUAÇÃO]]="ATIVO", IF(EPI[[#This Row],[CONDIÇÃO]]="N.A.", "N.A.", IF(EPI[[#This Row],[CONDIÇÃO]]="REPROVADO", "REPROVADO", IF(EPI[[#This Row],[CONDIÇÃO]]="RECICLADO", "HISTORICO", IF(EPI[[#This Row],[CONDIÇÃO]]="SEM REGISTRO", "SEM REGISTRO", IF(G392="01/01/1900", "SEM REGISTRO", IF((G3+H3)>TODAY(), "NO PRAZO", "VENCIDO" ) ) ) ) ) ),"N.A.") -> HISTORICO | J3: =EPI[[#This Row],[TREINADO EM]]+EPI[[#This Row],[VALIDADE]] -> 45457 | K3: 1 | L3: RECICLADO | M3: =VLOOKUP(EPI[[#This Row],[NOME]],'CADASTRO'!A:K,6,0) -> ATIVO
A4: INTERNO | B4: PIU JDE | C4: ROMULO GONCALVES PEREIRA BRAGA | D4: NR 06 EPI | E4: ALEX BARBARA | F4: =VLOOKUP(EPI[[#This Row],[NOME]],'CADASTRO'!A:K,5,0) -> TECNICO MECANICO II | G4: 45279 | H4: 365 | I4: =IF(EPI[[#This Row],[SITUAÇÃO]]="ATIVO", IF(EPI[[#This Row],[CONDIÇÃO]]="N.A.", "N.A.", IF(EPI[[#This Row],[CONDIÇÃO]]="REPROVADO", "REPROVADO", IF(EPI[[#This Row],[CONDIÇÃO]]="RECICLADO", "HISTORICO", IF(EPI[[#This Row],[CONDIÇÃO]]="SEM REGISTRO", "SEM REGISTRO", IF(G393="01/01/1900", "SEM REGISTRO", IF((G4+H4)>TODAY(), "NO PRAZO", "VENCIDO" ) ) ) ) ) ),"N.A.") -> HISTORICO | J4: =EPI[[#This Row],[TREINADO EM]]+EPI[[#This Row],[VALIDADE]] -> 45644 | K4: 1 | L4: RECICLADO | M4: =VLOOKUP(EPI[[#This Row],[NOME]],'CADASTRO'!A:K,6,0) -> ATIVO
A5: INTERNO | B5: PIU JDE | C5: GUILHERME DOS REIS OLIVEIRA | D5: NR 06 EPI | E5: ALEX BARBARA | F5: =VLOOKUP(EPI[[#This Row],[NOME]],'CADASTRO'!A:K,5,0) -> TECNICO MECANICO II | G5: 46293 | H5: 365 | I5: =IF(EPI[[#This Row],[SITUAÇÃO]]="ATIVO", IF(EPI[[#This Row],[CONDIÇÃO]]="N.A.", "N.A.", IF(EPI[[#This Row],[CONDIÇÃO]]="REPROVADO", "REPROVADO", IF(EPI[[#This Row],[CONDIÇÃO]]="RECICLADO", "HISTORICO", IF(EPI[[#This Row],[CONDIÇÃO]]="SEM REGISTRO", "SEM REGISTRO", IF(G394="01/01/1900", "SEM REGISTRO", IF((G5+H5)>TODAY(), "NO PRAZO", "VENCIDO" ) ) ) ) ) ),"N.A.") -> NO PRAZO | J5: =EPI[[#This Row],[TREINADO EM]]+EPI[[#This Row],[VALIDADE]] -> 46658 | K5: 1 | L5: APROVADO | M5: =VLOOKUP(EPI[[#This Row],[NOME]],'CADASTRO'!A:K,6,0) -> ATIVO
A6: INTERNO | B6: PIU JDE | C6: GUILHERME DOS REIS OLIVEIRA | D6: NR 06 EPI | E6: ALEX SANDRO ALVES TEIXEIRA | F6: =VLOOKUP(EPI[[#This Row],[NOME]],'CADASTRO'!A:K,5,0) -> OPERADOR INDUSTRIAL II | G6: 44928 | H6: 365 | I6: =IF(EPI[[#This Row],[SITUAÇÃO]]="ATIVO", IF(EPI[[#This Row],[CONDIÇÃO]]="N.A.", "N.A.", IF(EPI[[#This Row],[CONDIÇÃO]]="REPROVADO", "REPROVADO", IF(EPI[[#This Row],[CONDIÇÃO]]="RECICLADO", "HISTORICO", IF(EPI[[#This Row],[CONDIÇÃO]]="SEM REGISTRO", "SEM REGISTRO", IF(G395="01/01/1900", "SEM REGISTRO", IF((G6+H6)>TODAY(), "NO PRAZO", "VENCIDO" ) ) ) ) ) ),"N.A.") -> HISTORICO | J6: =EPI[[#This Row],[TREINADO EM]]+EPI[[#This Row],[VALIDADE]] -> 45293 | K6: 1 | L6: RECICLADO | M6: =VLOOKUP(EPI[[#This Row],[NOME]],'CADASTRO'!A:K,6,0) -> ATIVO
A7: INTERNO | B7: PIU JDE | C7: ROMULO GONCALVES PEREIRA BRAGA | D7: NR 06 EPI | E7: ALEX SANDRO ALVES TEIXEIRA | F7: =VLOOKUP(EPI[[#This Row],[NOME]],'CADASTRO'!A:K,5,0) -> OPERADOR INDUSTRIAL II | G7: 45279 | H7: 365 | I7: =IF(EPI[[#This Row],[SITUAÇÃO]]="ATIVO", IF(EPI[[#This Row],[CONDIÇÃO]]="N.A.", "N.A.", IF(EPI[[#This Row],[CONDIÇÃO]]="REPROVADO", "REPROVADO", IF(EPI[[#This Row],[CONDIÇÃO]]="RECICLADO", "HISTORICO", IF(EPI[[#This Row],[CONDIÇÃO]]="SEM REGISTRO", "SEM REGISTRO", IF(G396="01/01/1900", "SEM REGISTRO", IF((G7+H7)>TODAY(), "NO PRAZO", "VENCIDO" ) ) ) ) ) ),"N.A.") -> HISTORICO | J7: =EPI[[#This Row],[TREINADO EM]]+EPI[[#This Row],[VALIDADE]] -> 45644 | K7: 1 | L7: RECICLADO | M7: =VLOOKUP(EPI[[#This Row],[NOME]],'CADASTRO'!A:K,6,0) -> ATIVO
A8: INTERNO | B8: PIU JDE | C8: GUILHERME DOS REIS OLIVEIRA | D8: NR 06 EPI | E8: ALEX SANDRO ALVES TEIXEIRA | F8: =VLOOKUP(EPI[[#This Row],[NOME]],'CADASTRO'!A:K,5,0) -> OPERADOR INDUSTRIAL II | G8: 45645 | H8: 365 | I8: =IF(EPI[[#This Row],[SITUAÇÃO]]="ATIVO", IF(EPI[[#This Row],[CONDIÇÃO]]="N.A.", "N.A.", IF(EPI[[#This Row],[CONDIÇÃO]]="REPROVADO", "REPROVADO", IF(EPI[[#This Row],[CONDIÇÃO]]="RECICLADO", "HISTORICO", IF(EPI[[#This Row],[CONDIÇÃO]]="SEM REGISTRO", "SEM REGISTRO", IF(G397="01/01/1900", "SEM REGISTRO", IF((G8+H8)>TODAY(), "NO PRAZO", "VENCIDO" ) ) ) ) ) ),"N.A.") -> HISTORICO | J8: =EPI[[#This Row],[TREINADO EM]]+EPI[[#This Row],[VALIDADE]] -> 46010 | K8: 1 | L8: RECICLADO | M8: =VLOOKUP(EPI[[#This Row],[NOME]],'CADASTRO'!A:K,6,0) -> ATIVO
A9: INTERNO | B9: PIU JDE | C9: GUILHERME DOS REIS OLIVEIRA | D9: NR 06 EPI | E9: ALEX SANDRO ALVES TEIXEIRA | F9: =VLOOKUP(EPI[[#This Row],[NOME]],'CADASTRO'!A:K,5,0) -> OPERADOR INDUSTRIAL II | G9: 46009 | H9: 365 | I9: =IF(EPI[[#This Row],[SITUAÇÃO]]="ATIVO", IF(EPI[[#This Row],[CONDIÇÃO]]="N.A.", "N.A.", IF(EPI[[#This Row],[CONDIÇÃO]]="REPROVADO", "REPROVADO", IF(EPI[[#This Row],[CONDIÇÃO]]="RECICLADO", "HISTORICO", IF(EPI[[#This Row],[CONDIÇÃO]]="SEM REGISTRO", "SEM REGISTRO", IF(G398="01/01/1900", "SEM REGISTRO", IF((G9+H9)>TODAY(), "NO PRAZO", "VENCIDO" ) ) ) ) ) ),"N.A.") -> HISTORICO | J9: =EPI[[#This Row],[TREINADO EM]]+EPI[[#This Row],[VALIDADE]] -> 46374 | K9: 1 | L9: RECICLADO | M9: =VLOOKUP(EPI[[#This Row],[NOME]],'CADASTRO'!A:K,6,0) -> ATIVO
A10: INTERNO | B10: PIU JDE | C10: GUILHERME DOS REIS OLIVEIRA | D10: NR 06 EPI | E10: ALEX SANDRO ALVES TEIXEIRA | F10: =VLOOKUP(EPI[[#This Row],[NOME]],'CADASTRO'!A:K,5,0) -> OPERADOR INDUSTRIAL II | G10: 46211.536 | H10: 183 | I10: =IF(EPI[[#This Row],[SITUAÇÃO]]="ATIVO", IF(EPI[[#This Row],[CONDIÇÃO]]="N.A.", "N.A.", IF(EPI[[#This Row],[CONDIÇÃO]]="REPROVADO", "REPROVADO", IF(EPI[[#This Row],[CONDIÇÃO]]="RECICLADO", "HISTORICO", IF(EPI[[#This Row],[CONDIÇÃO]]="SEM REGISTRO", "SEM REGISTRO", IF(G399="01/01/1900", "SEM REGISTRO", IF((G10+H10)>TODAY(), "NO PRAZO", "VENCIDO" ) ) ) ) ) ),"N.A.") -> NO PRAZO | J10: =EPI[[#This Row],[TREINADO EM]]+EPI[[#This Row],[VALIDADE]] -> 46394.536 | K10: 1 | L10: APROVADO | M10: =VLOOKUP(EPI[[#This Row],[NOME]],'CADASTRO'!A:K,6,0) -> ATIVO | N10: 12-05-2026 EPI
A11: INTERNO | B11: PIU JDE | C11: ROMULO GONCALVES PEREIRA BRAGA | D11: NR 06 EPI | E11: ALEX WILSON JOSE BERNARDES | F11: =VLOOKUP(EPI[[#This Row],[NOME]],'CADASTRO'!A:K,5,0) -> OPERADOR LOGISTICO I | G11: 45253 | H11: 365 | I11: =IF(EPI[[#This Row],[SITUAÇÃO]]="ATIVO", IF(EPI[[#This Row],[CONDIÇÃO]]="N.A.", "N.A.", IF(EPI[[#This Row],[CONDIÇÃO]]="REPROVADO", "REPROVADO", IF(EPI[[#This Row],[CONDIÇÃO]]="RECICLADO", "HISTORICO", IF(EPI[[#This Row],[CONDIÇÃO]]="SEM REGISTRO", "SEM REGISTRO", IF(G400="01/01/1900", "SEM REGISTRO", IF((G11+H11)>TODAY(), "NO PRAZO", "VENCIDO" ) ) ) ) ) ),"N.A.") -> N.A. | J11: =EPI[[#This Row],[TREINADO EM]]+EPI[[#This Row],[VALIDADE]] -> 45618 | K11: 1 | L11: RECICLADO | M11: =VLOOKUP(EPI[[#This Row],[NOME]],'CADASTRO'!A:K,6,0) -> DESLIGADO
A12: INTERNO | B12: PIU JDE | C12: ROMULO GONCALVES PEREIRA BRAGA | D12: NR 06 EPI | E12: ALEX WILSON JOSE BERNARDES | F12: =VLOOKUP(EPI[[#This Row],[NOME]],'CADASTRO'!A:K,5,0) -> OPERADOR LOGISTICO I | G12: 45279 | H12: 365 | I12: =IF(EPI[[#This Row],[SITUAÇÃO]]="ATIVO", IF(EPI[[#This Row],[CONDIÇÃO]]="N.A.", "N.A.", IF(EPI[[#This Row],[CONDIÇÃO]]="REPROVADO", "REPROVADO", IF(EPI[[#This Row],[CONDIÇÃO]]="RECICLADO", "HISTORICO", IF(EPI[[#This Row],[CONDIÇÃO]]="SEM REGISTRO", "SEM REGISTRO", IF(G401="01/01/1900", "SEM REGISTRO", IF((G12+H12)>TODAY(), "NO PRAZO", "VENCIDO" ) ) ) ) ) ),"N.A.") -> N.A. | J12: =EPI[[#This Row],[TREINADO EM]]+EPI[[#This Row],[VALIDADE]] -> 45644 | K12: 1 | L12: RECICLADO | M12: =VLOOKUP(EPI[[#This Row],[NOME]],'CADASTRO'!A:K,6,0) -> DESLIGADO
A13: INTERNO | B13: PIU JDE | C13: TIAGO TEIXEIRA DE CARVALHO | D13: NR 06 EPI | E13: ALEX WILSON JOSE BERNARDES | F13: =VLOOKUP(EPI[[#This Row],[NOME]],'CADASTRO'!A:K,5,0) -> OPERADOR LOGISTICO I | G13: 45645 | H13: 365 | I13: =IF(EPI[[#This Row],[SITUAÇÃO]]="ATIVO", IF(EPI[[#This Row],[CONDIÇÃO]]="N.A.", "N.A.", IF(EPI[[#This Row],[CONDIÇÃO]]="REPROVADO", "REPROVADO", IF(EPI[[#This Row],[CONDIÇÃO]]="RECICLADO", "HISTORICO", IF(EPI[[#This Row],[CONDIÇÃO]]="SEM REGISTRO", "SEM REGISTRO", IF(G402="01/01/1900", "SEM REGISTRO", IF((G13+H13)>TODAY(), "NO PRAZO", "VENCIDO" ) ) ) ) ) ),"N.A.") -> N.A. | J13: =EPI[[#This Row],[TREINADO EM]]+EPI[[#This Row],[VALIDADE]] -> 46010 | K13: 1 | L13: RECICLADO | M13: =VLOOKUP(EPI[[#This Row],[NOME]],'CADASTRO'!A:K,6,0) -> DESLIGADO
A14: INTERNO | B14: PIU JDE | C14: GUILHERME DOS REIS OLIVEIRA | D14: NR 06 EPI | E14: ALEX WILSON JOSE BERNARDES | F14: =VLOOKUP(EPI[[#This Row],[NOME]],'CADASTRO'!A:K,5,0) -> OPERADOR LOGISTICO I | G14: 46009 | H14: 365 | I14: =IF(EPI[[#This Row],[SITUAÇÃO]]="ATIVO", IF(EPI[[#This Row],[CONDIÇÃO]]="N.A.", "N.A.", IF(EPI[[#This Row],[CONDIÇÃO]]="REPROVADO", "REPROVADO", IF(EPI[[#This Row],[CONDIÇÃO]]="RECICLADO", "HISTORICO", IF(EPI[[#This Row],[CONDIÇÃO]]="SEM REGISTRO", "SEM REGISTRO", IF(G403="01/01/1900", "SEM REGISTRO", IF((G14+H14)>TODAY(), "NO PRAZO", "VENCIDO" ) ) ) ) ) ),"N.A.") -> N.A. | J14: =EPI[[#This Row],[TREINADO EM]]+EPI[[#This Row],[VALIDADE]] -> 46374 | K14: 1 | L14: APROVADO | M14: =VLOOKUP(EPI[[#This Row],[NOME]],'CADASTRO'!A:K,6,0) -> DESLIGADO | N14: EPI 18-12-2025
A15: INTERNO | B15: PIU JDE | C15: GUILHERME DOS REIS OLIVEIRA | D15: NR 06 EPI | E15: ALEXANDRE BATISTA DE OLIVEIRA | F15: =VLOOKUP(EPI[[#This Row],[NOME]],'CADASTRO'!A:K,5,0) -> TECNICO MECANICO III | G15: 44928 | H15: 365 | I15: =IF(EPI[[#This Row],[SITUAÇÃO]]="ATIVO", IF(EPI[[#This Row],[CONDIÇÃO]]="N.A.", "N.A.", IF(EPI[[#This Row],[CONDIÇÃO]]="REPROVADO", "REPROVADO", IF(EPI[[#This Row],[CONDIÇÃO]]="RECICLADO", "HISTORICO", IF(EPI[[#This Row],[CONDIÇÃO]]="SEM REGISTRO", "SEM REGISTRO", IF(G404="01/01/1900", "SEM REGISTRO", IF((G15+H15)>TODAY(), "NO PRAZO", "VENCIDO" ) ) ) ) ) ),"N.A.") -> HISTORICO | J15: =EPI[[#This Row],[TREINADO EM]]+EPI[[#This Row],[VALIDADE]] -> 45293 | K15: 1 | L15: RECICLADO | M15: =VLOOKUP(EPI[[#This Row],[NOME]],'CADASTRO'!A:K,6,0) -> ATIVO
A16: INTERNO | B16: PIU JDE | C16: ROMULO GONCALVES PEREIRA BRAGA | D16: NR 06 EPI | E16: ALEXANDRE BATISTA DE OLIVEIRA | F16: =VLOOKUP(EPI[[#This Row],[NOME]],'CADASTRO'!A:K,5,0) -> TECNICO MECANICO III | G16: 45358 | H16: 365 | I16: =IF(EPI[[#This Row],[SITUAÇÃO]]="ATIVO", IF(EPI[[#This Row],[CONDIÇÃO]]="N.A.", "N.A.", IF(EPI[[#This Row],[CONDIÇÃO]]="REPROVADO", "REPROVADO", IF(EPI[[#This Row],[CONDIÇÃO]]="RECICLADO", "HISTORICO", IF(EPI[[#This Row],[CONDIÇÃO]]="SEM REGISTRO", "SEM REGISTRO", IF(G405="01/01/1900", "SEM REGISTRO", IF((G16+H16)>TODAY(), "NO PRAZO", "VENCIDO" ) ) ) ) ) ),"N.A.") -> HISTORICO | J16: =EPI[[#This Row],[TREINADO EM]]+EPI[[#This Row],[VALIDADE]] -> 45723 | K16: 1 | L16: RECICLADO | M16: =VLOOKUP(EPI[[#This Row],[NOME]],'CADASTRO'!A:K,6,0) -> ATIVO
A17: INTERNO | B17: PIU JDE | C17: GUILHERME DOS REIS OLIVEIRA | D17: NR 06 EPI | E17: ALEXANDRE BATISTA DE OLIVEIRA | F17: =VLOOKUP(EPI[[#This Row],[NOME]],'CADASTRO'!A:K,5,0) -> TECNICO MECANICO III | G17: 45645 | H17: 365 | I17: =IF(EPI[[#This Row],[SITUAÇÃO]]="ATIVO", IF(EPI[[#This Row],[CONDIÇÃO]]="N.A.", "N.A.", IF(EPI[[#This Row],[CONDIÇÃO]]="REPROVADO", "REPROVADO", IF(EPI[[#This Row],[CONDIÇÃO]]="RECICLADO", "HISTORICO", IF(EPI[[#This Row],[CONDIÇÃO]]="SEM REGISTRO", "SEM REGISTRO", IF(G406="01/01/1900", "SEM REGISTRO", IF((G17+H17)>TODAY(), "NO PRAZO", "VENCIDO" ) ) ) ) ) ),"N.A.") -> HISTORICO | J17: =EPI[[#This Row],[TREINADO EM]]+EPI[[#This Row],[VALIDADE]] -> 46010 | K17: 1 | L17: RECICLADO | M17: =VLOOKUP(EPI[[#This Row],[NOME]],'CADASTRO'!A:K,6,0) -> ATIVO
A18: INTERNO | B18: PIU JDE | C18: GUILHERME DOS REIS OLIVEIRA | D18: NR 06 EPI | E18: ALEXANDRE BATISTA DE OLIVEIRA | F18: =VLOOKUP(EPI[[#This Row],[NOME]],'CADASTRO'!A:K,5,0) -> TECNICO MECANICO III | G18: 46211.567 | H18: 183 | I18: =IF(EPI[[#This Row],[SITUAÇÃO]]="ATIVO", IF(EPI[[#This Row],[CONDIÇÃO]]="N.A.", "N.A.", IF(EPI[[#This Row],[CONDIÇÃO]]="REPROVADO", "REPROVADO", IF(EPI[[#This Row],[CONDIÇÃO]]="RECICLADO", "HISTORICO", IF(EPI[[#This Row],[CONDIÇÃO]]="SEM REGISTRO", "SEM REGISTRO", IF(G407="01/01/1900", "SEM REGISTRO", IF((G18+H18)>TODAY(), "NO PRAZO", "VENCIDO" ) ) ) ) ) ),"N.A.") -> NO PRAZO | J18: =EPI[[#This Row],[TREINADO EM]]+EPI[[#This Row],[VALIDADE]] -> 46394.567 | K18: 1 | L18: APROVADO | M18: =VLOOKUP(EPI[[#This Row],[NOME]],'CADASTRO'!A:K,6,0) -> ATIVO | N18: 12-05-2026 EPI
A19: INTERNO | B19: PIU JDE | C19: GUILHERME DOS REIS OLIVEIRA | D19: NR 06 EPI | E19: ALEXANDRE DE ASSIS DA COSTA | F19: =VLOOKUP(EPI[[#This Row],[NOME]],'CADASTRO'!A:K,5,0) -> TECNICO MECANICO II | G19: 44928 | H19: 365 | I19: =IF(EPI[[#This Row],[SITUAÇÃO]]="ATIVO", IF(EPI[[#This Row],[CONDIÇÃO]]="N.A.", "N.A.", IF(EPI[[#This Row],[CONDIÇÃO]]="REPROVADO", "REPROVADO", IF(EPI[[#This Row],[CONDIÇÃO]]="RECICLADO", "HISTORICO", IF(EPI[[#This Row],[CONDIÇÃO]]="SEM REGISTRO", "SEM REGISTRO", IF(G408="01/01/1900", "SEM REGISTRO", IF((G19+H19)>TODAY(), "NO PRAZO", "VENCIDO" ) ) ) ) ) ),"N.A.") -> HISTORICO | J19: =EPI[[#This Row],[TREINADO EM]]+EPI[[#This Row],[VALIDADE]] -> 45293 | K19: 1 | L19: RECICLADO | M19: =VLOOKUP(EPI[[#This Row],[NOME]],'CADASTRO'!A:K,6,0) -> ATIVO
A20: INTERNO | B20: PIU JDE | C20: ROMULO GONCALVES PEREIRA BRAGA | D20: NR 06 EPI | E20: ALEXANDRE DE ASSIS DA COSTA | F20: =VLOOKUP(EPI[[#This Row],[NOME]],'CADASTRO'!A:K,5,0) -> TECNICO MECANICO II | G20: 45279 | H20: 365 | I20: =IF(EPI[[#This Row],[SITUAÇÃO]]="ATIVO", IF(EPI[[#This Row],[CONDIÇÃO]]="N.A.", "N.A.", IF(EPI[[#This Row],[CONDIÇÃO]]="REPROVADO", "REPROVADO", IF(EPI[[#This Row],[CONDIÇÃO]]="RECICLADO", "HISTORICO", IF(EPI[[#This Row],[CONDIÇÃO]]="SEM REGISTRO", "SEM REGISTRO", IF(G409="01/01/1900", "SEM REGISTRO", IF((G20+H20)>TODAY(), "NO PRAZO", "VENCIDO" ) ) ) ) ) ),"N.A.") -> HISTORICO | J20: =EPI[[#This Row],[TREINADO EM]]+EPI[[#This Row],[VALIDADE]] -> 45644 | K20: 1 | L20: RECICLADO | M20: =VLOOKUP(EPI[[#This Row],[NOME]],'CADASTRO'!A:K,6,0) -> ATIVO
A21: INTERNO | B21: PIU JDE | C21: GUILHERME DOS REIS OLIVEIRA | D21: NR 06 EPI | E21: ALEXANDRE DE ASSIS DA COSTA | F21: =VLOOKUP(EPI[[#This Row],[NOME]],'CADASTRO'!A:K,5,0) -> TECNICO MECANICO II | G21: 45645 | H21: 365 | I21: =IF(EPI[[#This Row],[SITUAÇÃO]]="ATIVO", IF(EPI[[#This Row],[CONDIÇÃO]]="N.A.", "N.A.", IF(EPI[[#This Row],[CONDIÇÃO]]="REPROVADO", "REPROVADO", IF(EPI[[#This Row],[CONDIÇÃO]]="RECICLADO", "HISTORICO", IF(EPI[[#This Row],[CONDIÇÃO]]="SEM REGISTRO", "SEM REGISTRO", IF(G410="01/01/1900", "SEM REGISTRO", IF((G21+H21)>TODAY(), "NO PRAZO", "VENCIDO" ) ) ) ) ) ),"N.A.") -> HISTORICO | J21: =EPI[[#This Row],[TREINADO EM]]+EPI[[#This Row],[VALIDADE]] -> 46010 | K21: 1 | L21: RECICLADO | M21: =VLOOKUP(EPI[[#This Row],[NOME]],'CADASTRO'!A:K,6,0) -> ATIVO
A22: INTERNO | B22: PIU JDE | C22: GUILHERME DOS REIS OLIVEIRA | D22: NR 06 EPI | E22: ALEXANDRE DE ASSIS DA COSTA | F22: =VLOOKUP(EPI[[#This Row],[NOME]],'CADASTRO'!A:K,5,0) -> TECNICO MECANICO II | G22: 46211.982 | H22: 183 | I22: =IF(EPI[[#This Row],[SITUAÇÃO]]="ATIVO", IF(EPI[[#This Row],[CONDIÇÃO]]="N.A.", "N.A.", IF(EPI[[#This Row],[CONDIÇÃO]]="REPROVADO", "REPROVADO", IF(EPI[[#This Row],[CONDIÇÃO]]="RECICLADO", "HISTORICO", IF(EPI[[#This Row],[CONDIÇÃO]]="SEM REGISTRO", "SEM REGISTRO", IF(G411="01/01/1900", "SEM REGISTRO", IF((G22+H22)>TODAY(), "NO PRAZO", "VENCIDO" ) ) ) ) ) ),"N.A.") -> NO PRAZO | J22: =EPI[[#This Row],[TREINADO EM]]+EPI[[#This Row],[VALIDADE]] -> 46394.982 | K22: 1 | L22: APROVADO | M22: =VLOOKUP(EPI[[#This Row],[NOME]],'CADASTRO'!A:K,6,0) -> ATIVO | N22: 12-05-2026 EPI
A23: INTERNO | B23: PIU JDE | C23: GUILHERME DOS REIS OLIVEIRA | D23: NR 06 EPI | E23: ALICE RAMOS MORAIS | F23: =VLOOKUP(EPI[[#This Row],[NOME]],'CADASTRO'!A:K,5,0) -> ANALISTA GESTAO QUALIDADE PL | G23: 46098 | H23: 365 | I23: =IF(EPI[[#This Row],[SITUAÇÃO]]="ATIVO", IF(EPI[[#This Row],[CONDIÇÃO]]="N.A.", "N.A.", IF(EPI[[#This Row],[CONDIÇÃO]]="REPROVADO", "REPROVADO", IF(EPI[[#This Row],[CONDIÇÃO]]="RECICLADO", "HISTORICO", IF(EPI[[#This Row],[CONDIÇÃO]]="SEM REGISTRO", "SEM REGISTRO", IF(G412="01/01/1900", "SEM REGISTRO", IF((G23+H23)>TODAY(), "NO PRAZO", "VENCIDO" ) ) ) ) ) ),"N.A.") -> NO PRAZO | J23: =EPI[[#This Row],[TREINADO EM]]+EPI[[#This Row],[VALIDADE]] -> 46463 | K23: 1 | L23: APROVADO | M23: =VLOOKUP(EPI[[#This Row],[NOME]],'CADASTRO'!A:K,6,0) -> ATIVO | N23: EPI 17-03-2026
A24: INTERNO | B24: PIU JDE | C24: GUILHERME DOS REIS OLIVEIRA | D24: NR 06 EPI | E24: ALINE FERNANDES | F24: =VLOOKUP(EPI[[#This Row],[NOME]],'CADASTRO'!A:K,5,0) -> ASSISTENTE ADMINISTRATIVO | G24: 45274 | H24: 365 | I24: =IF(EPI[[#This Row],[SITUAÇÃO]]="ATIVO", IF(EPI[[#This Row],[CONDIÇÃO]]="N.A.", "N.A.", IF(EPI[[#This Row],[CONDIÇÃO]]="REPROVADO", "REPROVADO", IF(EPI[[#This Row],[CONDIÇÃO]]="RECICLADO", "HISTORICO", IF(EPI[[#This Row],[CONDIÇÃO]]="SEM REGISTRO", "SEM REGISTRO", IF(G413="01/01/1900", "SEM REGISTRO", IF((G24+H24)>TODAY(), "NO PRAZO", "VENCIDO" ) ) ) ) ) ),"N.A.") -> HISTORICO | J24: =EPI[[#This Row],[TREINADO EM]]+EPI[[#This Row],[VALIDADE]] -> 45639 | K24: 1 | L24: RECICLADO | M24: =VLOOKUP(EPI[[#This Row],[NOME]],'CADASTRO'!A:K,6,0) -> ATIVO
A25: INTERNO | B25: PIU JDE | C25: GUILHERME DOS REIS OLIVEIRA | D25: NR 06 EPI | E25: ALINE FERNANDES | F25: =VLOOKUP(EPI[[#This Row],[NOME]],'CADASTRO'!A:K,5,0) -> ASSISTENTE ADMINISTRATIVO | G25: 45826 | H25: 365 | I25: =IF(EPI[[#This Row],[SITUAÇÃO]]="ATIVO", IF(EPI[[#This Row],[CONDIÇÃO]]="N.A.", "N.A.", IF(EPI[[#This Row],[CONDIÇÃO]]="REPROVADO", "REPROVADO", IF(EPI[[#This Row],[CONDIÇÃO]]="RECICLADO", "HISTORICO", IF(EPI[[#This Row],[CONDIÇÃO]]="SEM REGISTRO", "SEM REGISTRO", IF(G414="01/01/1900", "SEM REGISTRO", IF((G25+H25)>TODAY(), "NO PRAZO", "VENCIDO" ) ) ) ) ) ),"N.A.") -> HISTORICO | J25: =EPI[[#This Row],[TREINADO EM]]+EPI[[#This Row],[VALIDADE]] -> 46191 | K25: 1 | L25: RECICLADO | M25: =VLOOKUP(EPI[[#This Row],[NOME]],'CADASTRO'!A:K,6,0) -> ATIVO
A26: INTERNO | B26: PIU JDE | C26: GUILHERME DOS REIS OLIVEIRA | D26: NR 06 EPI | E26: ALINE FERNANDES | F26: =VLOOKUP(EPI[[#This Row],[NOME]],'CADASTRO'!A:K,5,0) -> ASSISTENTE ADMINISTRATIVO | G26: 46176 | H26: 365 | I26: =IF(EPI[[#This Row],[SITUAÇÃO]]="ATIVO", IF(EPI[[#This Row],[CONDIÇÃO]]="N.A.", "N.A.", IF(EPI[[#This Row],[CONDIÇÃO]]="REPROVADO", "REPROVADO", IF(EPI[[#This Row],[CONDIÇÃO]]="RECICLADO", "HISTORICO", IF(EPI[[#This Row],[CONDIÇÃO]]="SEM REGISTRO", "SEM REGISTRO", IF(G415="01/01/1900", "SEM REGISTRO", IF((G26+H26)>TODAY(), "NO PRAZO", "VENCIDO" ) ) ) ) ) ),"N.A.") -> NO PRAZO | J26: =EPI[[#This Row],[TREINADO EM]]+EPI[[#This Row],[VALIDADE]] -> 46541 | K26: 1 | L26: APROVADO | M26: =VLOOKUP(EPI[[#This Row],[NOME]],'CADASTRO'!A:K,6,0) -> ATIVO | N26: 12-05-2026 EPI
A27: INTERNO | B27: PIU JDE | C27: GUILHERME DOS REIS OLIVEIRA | D27: NR 06 EPI | E27: ANA BEATRIZ LIMA SILVA | F27: =VLOOKUP(EPI[[#This Row],[NOME]],'CADASTRO'!A:K,5,0) -> ESTAGIARIO | G27: 46182 | H27: 365 | I27: =IF(EPI[[#This Row],[SITUAÇÃO]]="ATIVO", IF(EPI[[#This Row],[CONDIÇÃO]]="N.A.", "N.A.", IF(EPI[[#This Row],[CONDIÇÃO]]="REPROVADO", "REPROVADO", IF(EPI[[#This Row],[CONDIÇÃO]]="RECICLADO", "HISTORICO", IF(EPI[[#This Row],[CONDIÇÃO]]="SEM REGISTRO", "SEM REGISTRO", IF(G416="01/01/1900", "SEM REGISTRO", IF((G27+H27)>TODAY(), "NO PRAZO", "VENCIDO" ) ) ) ) ) ),"N.A.") -> NO PRAZO | J27: =EPI[[#This Row],[TREINADO EM]]+EPI[[#This Row],[VALIDADE]] -> 46547 | K27: 1 | L27: APROVADO | M27: =VLOOKUP(EPI[[#This Row],[NOME]],'CADASTRO'!A:K,6,0) -> ATIVO | N27: 12-05-2026 EPI
A28: INTERNO | B28: PIU JDE | C28: GUILHERME DOS REIS OLIVEIRA | D28: NR 06 EPI | E28: ANA CAROLLINE SIQUEIRA MARTINS | F28: =VLOOKUP(EPI[[#This Row],[NOME]],'CADASTRO'!A:K,5,0) -> ASSISTENTE ADMINISTRATIVO | G28: 45826 | H28: 365 | I28: =IF(EPI[[#This Row],[SITUAÇÃO]]="ATIVO", IF(EPI[[#This Row],[CONDIÇÃO]]="N.A.", "N.A.", IF(EPI[[#This Row],[CONDIÇÃO]]="REPROVADO", "REPROVADO", IF(EPI[[#This Row],[CONDIÇÃO]]="RECICLADO", "HISTORICO", IF(EPI[[#This Row],[CONDIÇÃO]]="SEM REGISTRO", "SEM REGISTRO", IF(G417="01/01/1900", "SEM REGISTRO", IF((G28+H28)>TODAY(), "NO PRAZO", "VENCIDO" ) ) ) ) ) ),"N.A.") -> HISTORICO | J28: =EPI[[#This Row],[TREINADO EM]]+EPI[[#This Row],[VALIDADE]] -> 46191 | K28: 1 | L28: RECICLADO | M28: =VLOOKUP(EPI[[#This Row],[NOME]],'CADASTRO'!A:K,6,0) -> ATIVO
A29: INTERNO | B29: PIU JDE | C29: GUILHERME DOS REIS OLIVEIRA | D29: NR 06 EPI | E29: ANA CAROLLINE SIQUEIRA MARTINS | F29: =VLOOKUP(EPI[[#This Row],[NOME]],'CADASTRO'!A:K,5,0) -> ASSISTENTE ADMINISTRATIVO | G29: 45882 | H29: 365 | I29: =IF(EPI[[#This Row],[SITUAÇÃO]]="ATIVO", IF(EPI[[#This Row],[CONDIÇÃO]]="N.A.", "N.A.", IF(EPI[[#This Row],[CONDIÇÃO]]="REPROVADO", "REPROVADO", IF(EPI[[#This Row],[CONDIÇÃO]]="RECICLADO", "HISTORICO", IF(EPI[[#This Row],[CONDIÇÃO]]="SEM REGISTRO", "SEM REGISTRO", IF(G418="01/01/1900", "SEM REGISTRO", IF((G29+H29)>TODAY(), "NO PRAZO", "VENCIDO" ) ) ) ) ) ),"N.A.") -> HISTORICO | J29: =EPI[[#This Row],[TREINADO EM]]+EPI[[#This Row],[VALIDADE]] -> 46247 | K29: 1 | L29: RECICLADO | M29: =VLOOKUP(EPI[[#This Row],[NOME]],'CADASTRO'!A:K,6,0) -> ATIVO
A30: INTERNO | B30: PIU JDE | C30: GUILHERME DOS REIS OLIVEIRA | D30: NR 06 EPI | E30: ANA CAROLLINE SIQUEIRA MARTINS | F30: =VLOOKUP(EPI[[#This Row],[NOME]],'CADASTRO'!A:K,5,0) -> ASSISTENTE ADMINISTRATIVO | G30: 46269.583 | H30: 365 | I30: =IF(EPI[[#This Row],[SITUAÇÃO]]="ATIVO", IF(EPI[[#This Row],[CONDIÇÃO]]="N.A.", "N.A.", IF(EPI[[#This Row],[CONDIÇÃO]]="REPROVADO", "REPROVADO", IF(EPI[[#This Row],[CONDIÇÃO]]="RECICLADO", "HISTORICO", IF(EPI[[#This Row],[CONDIÇÃO]]="SEM REGISTRO", "SEM REGISTRO", IF(G419="01/01/1900", "SEM REGISTRO", IF((G30+H30)>TODAY(), "NO PRAZO", "VENCIDO" ) ) ) ) ) ),"N.A.") -> NO PRAZO | J30: =EPI[[#This Row],[TREINADO EM]]+EPI[[#This Row],[VALIDADE]] -> 46634.583 | K30: 1 | L30: APROVADO | M30: =VLOOKUP(EPI[[#This Row],[NOME]],'CADASTRO'!A:K,6,0) -> ATIVO | N30: 04-092026 EPI
A31: INTERNO | B31: PIU JDE | C31: GUILHERME DOS REIS OLIVEIRA | D31: NR 06 EPI | E31: ANA JULIA COSTA SILVA | F31: =VLOOKUP(EPI[[#This Row],[NOME]],'CADASTRO'!A:K,5,0) -> OPERADOR INDUSTRIAL I | G31: 45812 | H31: 365 | I31: =IF(EPI[[#This Row],[SITUAÇÃO]]="ATIVO", IF(EPI[[#This Row],[CONDIÇÃO]]="N.A.", "N.A.", IF(EPI[[#This Row],[CONDIÇÃO]]="REPROVADO", "REPROVADO", IF(EPI[[#This Row],[CONDIÇÃO]]="RECICLADO", "HISTORICO", IF(EPI[[#This Row],[CONDIÇÃO]]="SEM REGISTRO", "SEM REGISTRO", IF(G420="01/01/1900", "SEM REGISTRO", IF((G31+H31)>TODAY(), "NO PRAZO", "VENCIDO" ) ) ) ) ) ),"N.A.") -> HISTORICO | J31: =EPI[[#This Row],[TREINADO EM]]+EPI[[#This Row],[VALIDADE]] -> 46177 | K31: 1 | L31: RECICLADO | M31: =VLOOKUP(EPI[[#This Row],[NOME]],'CADASTRO'!A:K,6,0) -> ATIVO
A32: INTERNO | B32: PIU JDE | C32: GUILHERME DOS REIS OLIVEIRA | D32: NR 06 EPI | E32: ANA JULIA COSTA SILVA | F32: =VLOOKUP(EPI[[#This Row],[NOME]],'CADASTRO'!A:K,5,0) -> OPERADOR INDUSTRIAL I | G32: 46009 | H32: 365 | I32: =IF(EPI[[#This Row],[SITUAÇÃO]]="ATIVO", IF(EPI[[#This Row],[CONDIÇÃO]]="N.A.", "N.A.", IF(EPI[[#This Row],[CONDIÇÃO]]="REPROVADO", "REPROVADO", IF(EPI[[#This Row],[CONDIÇÃO]]="RECICLADO", "HISTORICO", IF(EPI[[#This Row],[CONDIÇÃO]]="SEM REGISTRO", "SEM REGISTRO", IF(G421="01/01/1900", "SEM REGISTRO", IF((G32+H32)>TODAY(), "NO PRAZO", "VENCIDO" ) ) ) ) ) ),"N.A.") -> NO PRAZO | J32: =EPI[[#This Row],[TREINADO EM]]+EPI[[#This Row],[VALIDADE]] -> 46374 | K32: 1 | L32: APROVADO | M32: =VLOOKUP(EPI[[#This Row],[NOME]],'CADASTRO'!A:K,6,0) -> ATIVO | N32: EPI 18-12-2025
A33: INTERNO | B33: PIU JDE | C33: GUILHERME DOS REIS OLIVEIRA | D33: NR 06 EPI | E33: ANA JULIA FARIA REZENDE | F33: =VLOOKUP(EPI[[#This Row],[NOME]],'CADASTRO'!A:K,5,0) -> ESTAGIARIO | G33: 45064 | H33: 365 | I33: =IF(EPI[[#This Row],[SITUAÇÃO]]="ATIVO", IF(EPI[[#This Row],[CONDIÇÃO]]="N.A.", "N.A.", IF(EPI[[#This Row],[CONDIÇÃO]]="REPROVADO", "REPROVADO", IF(EPI[[#This Row],[CONDIÇÃO]]="RECICLADO", "HISTORICO", IF(EPI[[#This Row],[CONDIÇÃO]]="SEM REGISTRO", "SEM REGISTRO", IF(G422="01/01/1900", "SEM REGISTRO", IF((G33+H33)>TODAY(), "NO PRAZO", "VENCIDO" ) ) ) ) ) ),"N.A.") -> N.A. | J33: =EPI[[#This Row],[TREINADO EM]]+EPI[[#This Row],[VALIDADE]] -> 45429 | K33: 1 | L33: APROVADO | M33: =VLOOKUP(EPI[[#This Row],[NOME]],'CADASTRO'!A:K,6,0) -> DESLIGADO
A34: INTERNO | B34: PIU JDE | C34: GUILHERME DOS REIS OLIVEIRA | D34: NR 06 EPI | E34: ANA LUISA FIGUEIREDO SILVA | F34: =VLOOKUP(EPI[[#This Row],[NOME]],'CADASTRO'!A:K,5,0) -> ASSISTENTE ADMINISTRATIVO | G34: 46126 | H34: 365 | I34: =IF(EPI[[#This Row],[SITUAÇÃO]]="ATIVO", IF(EPI[[#This Row],[CONDIÇÃO]]="N.A.", "N.A.", IF(EPI[[#This Row],[CONDIÇÃO]]="REPROVADO", "REPROVADO", IF(EPI[[#This Row],[CONDIÇÃO]]="RECICLADO", "HISTORICO", IF(EPI[[#This Row],[CONDIÇÃO]]="SEM REGISTRO", "SEM REGISTRO", IF(G423="01/01/1900", "SEM REGISTRO", IF((G34+H34)>TODAY(), "NO PRAZO", "VENCIDO" ) ) ) ) ) ),"N.A.") -> NO PRAZO | J34: =EPI[[#This Row],[TREINADO EM]]+EPI[[#This Row],[VALIDADE]] -> 46491 | K34: 1 | L34: APROVADO | M34: =VLOOKUP(EPI[[#This Row],[NOME]],'CADASTRO'!A:K,6,0) -> ATIVO
A35: INTERNO | B35: PIU JDE | C35: GUILHERME DOS REIS OLIVEIRA | D35: NR 06 EPI | E35: ANA LUISA SOARES PEREIRA | F35: =VLOOKUP(EPI[[#This Row],[NOME]],'CADASTRO'!A:K,5,0) -> ANALISTA FACILITIES | G35: 45092 | H35: 365 | I35: =IF(EPI[[#This Row],[SITUAÇÃO]]="ATIVO", IF(EPI[[#This Row],[CONDIÇÃO]]="N.A.", "N.A.", IF(EPI[[#This Row],[CONDIÇÃO]]="REPROVADO", "REPROVADO", IF(EPI[[#This Row],[CONDIÇÃO]]="RECICLADO", "HISTORICO", IF(EPI[[#This Row],[CONDIÇÃO]]="SEM REGISTRO", "SEM REGISTRO", IF(G424="01/01/1900", "SEM REGISTRO", IF((G35+H35)>TODAY(), "NO PRAZO", "VENCIDO" ) ) ) ) ) ),"N.A.") -> HISTORICO | J35: =EPI[[#This Row],[TREINADO EM]]+EPI[[#This Row],[VALIDADE]] -> 45457 | K35: 1 | L35: RECICLADO | M35: =VLOOKUP(EPI[[#This Row],[NOME]],'CADASTRO'!A:K,6,0) -> ATIVO
A36: INTERNO | B36: PIU JDE | C36: GUILHERME DOS REIS OLIVEIRA | D36: NR 06 EPI | E36: ANA LUISA SOARES PEREIRA | F36: =VLOOKUP(EPI[[#This Row],[NOME]],'CADASTRO'!A:K,5,0) -> ANALISTA FACILITIES | G36: 45547 | H36: 365 | I36: =IF(EPI[[#This Row],[SITUAÇÃO]]="ATIVO", IF(EPI[[#This Row],[CONDIÇÃO]]="N.A.", "N.A.", IF(EPI[[#This Row],[CONDIÇÃO]]="REPROVADO", "REPROVADO", IF(EPI[[#This Row],[CONDIÇÃO]]="RECICLADO", "HISTORICO", IF(EPI[[#This Row],[CONDIÇÃO]]="SEM REGISTRO", "SEM REGISTRO", IF(G425="01/01/1900", "SEM REGISTRO", IF((G36+H36)>TODAY(), "NO PRAZO", "VENCIDO" ) ) ) ) ) ),"N.A.") -> HISTORICO | J36: =EPI[[#This Row],[TREINADO EM]]+EPI[[#This Row],[VALIDADE]] -> 45912 | K36: 1 | L36: RECICLADO | M36: =VLOOKUP(EPI[[#This Row],[NOME]],'CADASTRO'!A:K,6,0) -> ATIVO
A37: INTERNO | B37: PIU JDE | C37: GUILHERME DOS REIS OLIVEIRA | D37: NR 06 EPI | E37: ANA LUISA SOARES PEREIRA | F37: =VLOOKUP(EPI[[#This Row],[NOME]],'CADASTRO'!A:K,5,0) -> ANALISTA FACILITIES | G37: 45903 | H37: 365 | I37: =IF(EPI[[#This Row],[SITUAÇÃO]]="ATIVO", IF(EPI[[#This Row],[CONDIÇÃO]]="N.A.", "N.A.", IF(EPI[[#This Row],[CONDIÇÃO]]="REPROVADO", "REPROVADO", IF(EPI[[#This Row],[CONDIÇÃO]]="RECICLADO", "HISTORICO", IF(EPI[[#This Row],[CONDIÇÃO]]="SEM REGISTRO", "SEM REGISTRO", IF(G426="01/01/1900", "SEM REGISTRO", IF((G37+H37)>TODAY(), "NO PRAZO", "VENCIDO" ) ) ) ) ) ),"N.A.") -> HISTORICO | J37: =EPI[[#This Row],[TREINADO EM]]+EPI[[#This Row],[VALIDADE]] -> 46268 | K37: 1 | L37: RECICLADO | M37: =VLOOKUP(EPI[[#This Row],[NOME]],'CADASTRO'!A:K,6,0) -> ATIVO
A38: INTERNO | B38: PIU JDE | C38: GUILHERME DOS REIS OLIVEIRA | D38: NR 06 EPI | E38: ANA LUISA SOARES PEREIRA | F38: =VLOOKUP(EPI[[#This Row],[NOME]],'CADASTRO'!A:K,5,0) -> ANALISTA FACILITIES | G38: 46280 | H38: 365 | I38: =IF(EPI[[#This Row],[SITUAÇÃO]]="ATIVO", IF(EPI[[#This Row],[CONDIÇÃO]]="N.A.", "N.A.", IF(EPI[[#This Row],[CONDIÇÃO]]="REPROVADO", "REPROVADO", IF(EPI[[#This Row],[CONDIÇÃO]]="RECICLADO", "HISTORICO", IF(EPI[[#This Row],[CONDIÇÃO]]="SEM REGISTRO", "SEM REGISTRO", IF(G427="01/01/1900", "SEM REGISTRO", IF((G38+H38)>TODAY(), "NO PRAZO", "VENCIDO" ) ) ) ) ) ),"N.A.") -> NO PRAZO | J38: =EPI[[#This Row],[TREINADO EM]]+EPI[[#This Row],[VALIDADE]] -> 46645 | K38: 1 | L38: APROVADO | M38: =VLOOKUP(EPI[[#This Row],[NOME]],'CADASTRO'!A:K,6,0) -> ATIVO
A39: INTERNO | B39: PIU JDE | C39: GUILHERME DOS REIS OLIVEIRA | D39: NR 06 EPI | E39: ANA LUIZA DE PAULA | F39: =VLOOKUP(EPI[[#This Row],[NOME]],'CADASTRO'!A:K,5,0) -> ANALISTA CONTROLE QUALIDADE JR | G39: 45568 | H39: 365 | I39: =IF(EPI[[#This Row],[SITUAÇÃO]]="ATIVO", IF(EPI[[#This Row],[CONDIÇÃO]]="N.A.", "N.A.", IF(EPI[[#This Row],[CONDIÇÃO]]="REPROVADO", "REPROVADO", IF(EPI[[#This Row],[CONDIÇÃO]]="RECICLADO", "HISTORICO", IF(EPI[[#This Row],[CONDIÇÃO]]="SEM REGISTRO", "SEM REGISTRO", IF(G428="01/01/1900", "SEM REGISTRO", IF((G39+H39)>TODAY(), "NO PRAZO", "VENCIDO" ) ) ) ) ) ),"N.A.") -> HISTORICO | J39: =EPI[[#This Row],[TREINADO EM]]+EPI[[#This Row],[VALIDADE]] -> 45933 | K39: 1 | L39: RECICLADO | M39: =VLOOKUP(EPI[[#This Row],[NOME]],'CADASTRO'!A:K,6,0) -> ATIVO
A40: INTERNO | B40: PIU JDE | C40: GUILHERME DOS REIS OLIVEIRA | D40: NR 06 EPI | E40: ANA LUIZA DE PAULA | F40: =VLOOKUP(EPI[[#This Row],[NOME]],'CADASTRO'!A:K,5,0) -> ANALISTA CONTROLE QUALIDADE JR | G40: 46098 | H40: 365 | I40: =IF(EPI[[#This Row],[SITUAÇÃO]]="ATIVO", IF(EPI[[#This Row],[CONDIÇÃO]]="N.A.", "N.A.", IF(EPI[[#This Row],[CONDIÇÃO]]="REPROVADO", "REPROVADO", IF(EPI[[#This Row],[CONDIÇÃO]]="RECICLADO", "HISTORICO", IF(EPI[[#This Row],[CONDIÇÃO]]="SEM REGISTRO", "SEM REGISTRO", IF(G429="01/01/1900", "SEM REGISTRO", IF((G40+H40)>TODAY(), "NO PRAZO", "VENCIDO" ) ) ) ) ) ),"N.A.") -> NO PRAZO | J40: =EPI[[#This Row],[TREINADO EM]]+EPI[[#This Row],[VALIDADE]] -> 46463 | K40: 1 | L40: APROVADO | M40: =VLOOKUP(EPI[[#This Row],[NOME]],'CADASTRO'!A:K,6,0) -> ATIVO | N40: EPI 17-03-2026
...

Sheet NR10
A1: ORIGEM | B1: FORNECEDOR | C1: INSTRUTOR | D1: TREINAMENTO | E1: NOME | F1: CARGO | G1: TREINADO EM | H1: VALIDADE | I1: STATUS | J1: VENCE EM | K1: CARGA HORARIA | L1: CONDIÇÃO | M1: SITUAÇÃO
A2: EXTERNO | B2: EXXCELENCIA | C2: VINICIUS FERREIRA | D2: NR 10 - BAIXA E MEDIA TENSAO | E2: ALCIMAR DOS SANTOS FARIA | F2: =VLOOKUP(NR10.BAIXATENSAO[[#This Row],[NOME]],'CADASTRO'!A:K,5,0) -> TECNICO ELETRONICO I | G2: 44252 | H2: 730 | I2: =IF(NR10.BAIXATENSAO[[#This Row],[SITUAÇÃO]]="ATIVO", IF(NR10.BAIXATENSAO[[#This Row],[CONDIÇÃO]]="N.A.", "N.A.", IF(NR10.BAIXATENSAO[[#This Row],[CONDIÇÃO]]="REPROVADO", "REPROVADO", IF(NR10.BAIXATENSAO[[#This Row],[CONDIÇÃO]]="RECICLADO", "HISTORICO", IF(NR10.BAIXATENSAO[[#This Row],[CONDIÇÃO]]="SEM REGISTRO", "SEM REGISTRO", IF(G333="01/01/1900", "SEM REGISTRO", IF((G2+H2)>TODAY(), "NO PRAZO", "VENCIDO" ) ) ) ) ) ),"N.A.") -> N.A. | J2: =NR10.BAIXATENSAO[[#This Row],[TREINADO EM]]+NR10.BAIXATENSAO[[#This Row],[VALIDADE]] -> 44982 | K2: 40 | L2: N.A. | M2: =VLOOKUP(NR10.BAIXATENSAO[[#This Row],[NOME]],'CADASTRO'!A:K,6,0) -> DESLIGADO
A3: EXTERNO | B3: MERITUS | C3: LUIZ SANTOS | D3: NR 10 - BAIXA E MEDIA TENSAO | E3: ANDERSON APARECIDO DO AMARAL | F3: =VLOOKUP(NR10.BAIXATENSAO[[#This Row],[NOME]],'CADASTRO'!A:K,5,0) -> TECNICO ELETRONICO II | G3: 46255 | H3: 730 | I3: =IF(NR10.BAIXATENSAO[[#This Row],[SITUAÇÃO]]="ATIVO", IF(NR10.BAIXATENSAO[[#This Row],[CONDIÇÃO]]="N.A.", "N.A.", IF(NR10.BAIXATENSAO[[#This Row],[CONDIÇÃO]]="REPROVADO", "REPROVADO", IF(NR10.BAIXATENSAO[[#This Row],[CONDIÇÃO]]="RECICLADO", "HISTORICO", IF(NR10.BAIXATENSAO[[#This Row],[CONDIÇÃO]]="SEM REGISTRO", "SEM REGISTRO", IF(G334="01/01/1900", "SEM REGISTRO", IF((G3+H3)>TODAY(), "NO PRAZO", "VENCIDO" ) ) ) ) ) ),"N.A.") -> NO PRAZO | J3: =NR10.BAIXATENSAO[[#This Row],[TREINADO EM]]+NR10.BAIXATENSAO[[#This Row],[VALIDADE]] -> 46985 | K3: 40 | L3: APROVADO | M3: =VLOOKUP(NR10.BAIXATENSAO[[#This Row],[NOME]],'CADASTRO'!A:K,6,0) -> ATIVO
A4: EXTERNO | B4: EXXCELENCIA | C4: VINICIUS FERREIRA | D4: NR 10 - BAIXA E MEDIA TENSAO | E4: ANGELO ROSEMBERG BELLO TEIXEIRA | F4: =VLOOKUP(NR10.BAIXATENSAO[[#This Row],[NOME]],'CADASTRO'!A:K,5,0) -> TECNICO ELETRONICO II | G4: 43930 | H4: 730 | I4: =IF(NR10.BAIXATENSAO[[#This Row],[SITUAÇÃO]]="ATIVO", IF(NR10.BAIXATENSAO[[#This Row],[CONDIÇÃO]]="N.A.", "N.A.", IF(NR10.BAIXATENSAO[[#This Row],[CONDIÇÃO]]="REPROVADO", "REPROVADO", IF(NR10.BAIXATENSAO[[#This Row],[CONDIÇÃO]]="RECICLADO", "HISTORICO", IF(NR10.BAIXATENSAO[[#This Row],[CONDIÇÃO]]="SEM REGISTRO", "SEM REGISTRO", IF(G335="01/01/1900", "SEM REGISTRO", IF((G4+H4)>TODAY(), "NO PRAZO", "VENCIDO" ) ) ) ) ) ),"N.A.") -> N.A. | J4: =NR10.BAIXATENSAO[[#This Row],[TREINADO EM]]+NR10.BAIXATENSAO[[#This Row],[VALIDADE]] -> 44660 | K4: 40 | L4: RECICLADO | M4: =VLOOKUP(NR10.BAIXATENSAO[[#This Row],[NOME]],'CADASTRO'!A:K,6,0) -> DESLIGADO
A5: EXTERNO | B5: EXXCELENCIA | C5: VINICIUS FERREIRA | D5: NR 10 - BAIXA E MEDIA TENSAO | E5: ANGELO ROSEMBERG BELLO TEIXEIRA | F5: =VLOOKUP(NR10.BAIXATENSAO[[#This Row],[NOME]],'CADASTRO'!A:K,5,0) -> TECNICO ELETRONICO II | G5: 44642 | H5: 730 | I5: =IF(NR10.BAIXATENSAO[[#This Row],[SITUAÇÃO]]="ATIVO", IF(NR10.BAIXATENSAO[[#This Row],[CONDIÇÃO]]="N.A.", "N.A.", IF(NR10.BAIXATENSAO[[#This Row],[CONDIÇÃO]]="REPROVADO", "REPROVADO", IF(NR10.BAIXATENSAO[[#This Row],[CONDIÇÃO]]="RECICLADO", "HISTORICO", IF(NR10.BAIXATENSAO[[#This Row],[CONDIÇÃO]]="SEM REGISTRO", "SEM REGISTRO", IF(G336="01/01/1900", "SEM REGISTRO", IF((G5+H5)>TODAY(), "NO PRAZO", "VENCIDO" ) ) ) ) ) ),"N.A.") -> N.A. | J5: =NR10.BAIXATENSAO[[#This Row],[TREINADO EM]]+NR10.BAIXATENSAO[[#This Row],[VALIDADE]] -> 45372 | K5: 8 | L5: RECICLADO | M5: =VLOOKUP(NR10.BAIXATENSAO[[#This Row],[NOME]],'CADASTRO'!A:K,6,0) -> DESLIGADO
A6: EXTERNO | B6: EXXCELENCIA | C6: SAYMON | D6: NR 10 - BAIXA E MEDIA TENSAO | E6: ANGELO ROSEMBERG BELLO TEIXEIRA | F6: =VLOOKUP(NR10.BAIXATENSAO[[#This Row],[NOME]],'CADASTRO'!A:K,5,0) -> TECNICO ELETRONICO II | G6: 45364 | H6: 730 | I6: =IF(NR10.BAIXATENSAO[[#This Row],[SITUAÇÃO]]="ATIVO", IF(NR10.BAIXATENSAO[[#This Row],[CONDIÇÃO]]="N.A.", "N.A.", IF(NR10.BAIXATENSAO[[#This Row],[CONDIÇÃO]]="REPROVADO", "REPROVADO", IF(NR10.BAIXATENSAO[[#This Row],[CONDIÇÃO]]="RECICLADO", "HISTORICO", IF(NR10.BAIXATENSAO[[#This Row],[CONDIÇÃO]]="SEM REGISTRO", "SEM REGISTRO", IF(G337="01/01/1900", "SEM REGISTRO", IF((G6+H6)>TODAY(), "NO PRAZO", "VENCIDO" ) ) ) ) ) ),"N.A.") -> N.A. | J6: =NR10.BAIXATENSAO[[#This Row],[TREINADO EM]]+NR10.BAIXATENSAO[[#This Row],[VALIDADE]] -> 46094 | K6: 16 | L6: APROVADO | M6: =VLOOKUP(NR10.BAIXATENSAO[[#This Row],[NOME]],'CADASTRO'!A:K,6,0) -> DESLIGADO
A7: EXTERNO | B7: EXXCELENCIA | C7: VINICIUS FERREIRA | D7: NR 10 - BAIXA E MEDIA TENSAO | E7: FABIO DE SOUZA COELHO | F7: =VLOOKUP(NR10.BAIXATENSAO[[#This Row],[NOME]],'CADASTRO'!A:K,5,0) -> TECNICO ELETRONICO III | G7: 44252 | H7: 730 | I7: =IF(NR10.BAIXATENSAO[[#This Row],[SITUAÇÃO]]="ATIVO", IF(NR10.BAIXATENSAO[[#This Row],[CONDIÇÃO]]="N.A.", "N.A.", IF(NR10.BAIXATENSAO[[#This Row],[CONDIÇÃO]]="REPROVADO", "REPROVADO", IF(NR10.BAIXATENSAO[[#This Row],[CONDIÇÃO]]="RECICLADO", "HISTORICO", IF(NR10.BAIXATENSAO[[#This Row],[CONDIÇÃO]]="SEM REGISTRO", "SEM REGISTRO", IF(G338="01/01/1900", "SEM REGISTRO", IF((G7+H7)>TODAY(), "NO PRAZO", "VENCIDO" ) ) ) ) ) ),"N.A.") -> HISTORICO | J7: =NR10.BAIXATENSAO[[#This Row],[TREINADO EM]]+NR10.BAIXATENSAO[[#This Row],[VALIDADE]] -> 44982 | K7: 40 | L7: RECICLADO | M7: =VLOOKUP(NR10.BAIXATENSAO[[#This Row],[NOME]],'CADASTRO'!A:K,6,0) -> ATIVO
A8: EXTERNO | B8: EXXCELENCIA | C8: VINICIUS FERREIRA | D8: NR 10 - BAIXA E MEDIA TENSAO | E8: FABIO DE SOUZA COELHO | F8: =VLOOKUP(NR10.BAIXATENSAO[[#This Row],[NOME]],'CADASTRO'!A:K,5,0) -> TECNICO ELETRONICO III | G8: 44966 | H8: 730 | I8: =IF(NR10.BAIXATENSAO[[#This Row],[SITUAÇÃO]]="ATIVO", IF(NR10.BAIXATENSAO[[#This Row],[CONDIÇÃO]]="N.A.", "N.A.", IF(NR10.BAIXATENSAO[[#This Row],[CONDIÇÃO]]="REPROVADO", "REPROVADO", IF(NR10.BAIXATENSAO[[#This Row],[CONDIÇÃO]]="RECICLADO", "HISTORICO", IF(NR10.BAIXATENSAO[[#This Row],[CONDIÇÃO]]="SEM REGISTRO", "SEM REGISTRO", IF(G339="01/01/1900", "SEM REGISTRO", IF((G8+H8)>TODAY(), "NO PRAZO", "VENCIDO" ) ) ) ) ) ),"N.A.") -> HISTORICO | J8: =NR10.BAIXATENSAO[[#This Row],[TREINADO EM]]+NR10.BAIXATENSAO[[#This Row],[VALIDADE]] -> 45696 | K8: 8 | L8: RECICLADO | M8: =VLOOKUP(NR10.BAIXATENSAO[[#This Row],[NOME]],'CADASTRO'!A:K,6,0) -> ATIVO
A9: EXTERNO | B9: EXXCELENCIA | C9: VINICIUS FERREIRA | D9: NR 10 - BAIXA E MEDIA TENSAO | E9: FABIO DE SOUZA COELHO | F9: =VLOOKUP(NR10.BAIXATENSAO[[#This Row],[NOME]],'CADASTRO'!A:K,5,0) -> TECNICO ELETRONICO III | G9: 45349 | H9: 730 | I9: =IF(NR10.BAIXATENSAO[[#This Row],[SITUAÇÃO]]="ATIVO", IF(NR10.BAIXATENSAO[[#This Row],[CONDIÇÃO]]="N.A.", "N.A.", IF(NR10.BAIXATENSAO[[#This Row],[CONDIÇÃO]]="REPROVADO", "REPROVADO", IF(NR10.BAIXATENSAO[[#This Row],[CONDIÇÃO]]="RECICLADO", "HISTORICO", IF(NR10.BAIXATENSAO[[#This Row],[CONDIÇÃO]]="SEM REGISTRO", "SEM REGISTRO", IF(G340="01/01/1900", "SEM REGISTRO", IF((G9+H9)>TODAY(), "NO PRAZO", "VENCIDO" ) ) ) ) ) ),"N.A.") -> HISTORICO | J9: =NR10.BAIXATENSAO[[#This Row],[TREINADO EM]]+NR10.BAIXATENSAO[[#This Row],[VALIDADE]] -> 46079 | K9: 16 | L9: RECICLADO | M9: =VLOOKUP(NR10.BAIXATENSAO[[#This Row],[NOME]],'CADASTRO'!A:K,6,0) -> ATIVO
A10: EXTERNO | B10: MERITUS | C10: FRANCIS RICARDO BARETTA | D10: NR 10 - BAIXA E MEDIA TENSAO | E10: FABIO DE SOUZA COELHO | F10: =VLOOKUP(NR10.BAIXATENSAO[[#This Row],[NOME]],'CADASTRO'!A:K,5,0) -> TECNICO ELETRONICO III | G10: 46076 | H10: 730 | I10: =IF(NR10.BAIXATENSAO[[#This Row],[SITUAÇÃO]]="ATIVO", IF(NR10.BAIXATENSAO[[#This Row],[CONDIÇÃO]]="N.A.", "N.A.", IF(NR10.BAIXATENSAO[[#This Row],[CONDIÇÃO]]="REPROVADO", "REPROVADO", IF(NR10.BAIXATENSAO[[#This Row],[CONDIÇÃO]]="RECICLADO", "HISTORICO", IF(NR10.BAIXATENSAO[[#This Row],[CONDIÇÃO]]="SEM REGISTRO", "SEM REGISTRO", IF(G341="01/01/1900", "SEM REGISTRO", IF((G10+H10)>TODAY(), "NO PRAZO", "VENCIDO" ) ) ) ) ) ),"N.A.") -> HISTORICO | J10: =NR10.BAIXATENSAO[[#This Row],[TREINADO EM]]+NR10.BAIXATENSAO[[#This Row],[VALIDADE]] -> 46806 | K10: 20 | L10: RECICLADO | M10: =VLOOKUP(NR10.BAIXATENSAO[[#This Row],[NOME]],'CADASTRO'!A:K,6,0) -> ATIVO
A11: EXTERNO | B11: MERITUS | C11: FRANCIS RICARDO BARETTA | D11: NR 10 - BAIXA E MEDIA TENSAO | E11: FABIO DE SOUZA COELHO | F11: =VLOOKUP(NR10.BAIXATENSAO[[#This Row],[NOME]],'CADASTRO'!A:K,5,0) -> TECNICO ELETRONICO III | G11: 46076 | H11: 730 | I11: =IF(NR10.BAIXATENSAO[[#This Row],[SITUAÇÃO]]="ATIVO", IF(NR10.BAIXATENSAO[[#This Row],[CONDIÇÃO]]="N.A.", "N.A.", IF(NR10.BAIXATENSAO[[#This Row],[CONDIÇÃO]]="REPROVADO", "REPROVADO", IF(NR10.BAIXATENSAO[[#This Row],[CONDIÇÃO]]="RECICLADO", "HISTORICO", IF(NR10.BAIXATENSAO[[#This Row],[CONDIÇÃO]]="SEM REGISTRO", "SEM REGISTRO", IF(G342="01/01/1900", "SEM REGISTRO", IF((G11+H11)>TODAY(), "NO PRAZO", "VENCIDO" ) ) ) ) ) ),"N.A.") -> NO PRAZO | J11: =NR10.BAIXATENSAO[[#This Row],[TREINADO EM]]+NR10.BAIXATENSAO[[#This Row],[VALIDADE]] -> 46806 | K11: 20 | L11: APROVADO | M11: =VLOOKUP(NR10.BAIXATENSAO[[#This Row],[NOME]],'CADASTRO'!A:K,6,0) -> ATIVO
A12: EXTERNO | B12: MERITUS | C12: LUIZ SANTOS | D12: NR 10 - BAIXA E MEDIA TENSAO | E12: GUILHERME DE PAULA SILVA | F12: =VLOOKUP(NR10.BAIXATENSAO[[#This Row],[NOME]],'CADASTRO'!A:K,5,0) -> TECNICO ELETRONICO I | G12: 46185 | H12: 730 | I12: =IF(NR10.BAIXATENSAO[[#This Row],[SITUAÇÃO]]="ATIVO", IF(NR10.BAIXATENSAO[[#This Row],[CONDIÇÃO]]="N.A.", "N.A.", IF(NR10.BAIXATENSAO[[#This Row],[CONDIÇÃO]]="REPROVADO", "REPROVADO", IF(NR10.BAIXATENSAO[[#This Row],[CONDIÇÃO]]="RECICLADO", "HISTORICO", IF(NR10.BAIXATENSAO[[#This Row],[CONDIÇÃO]]="SEM REGISTRO", "SEM REGISTRO", IF(G343="01/01/1900", "SEM REGISTRO", IF((G12+H12)>TODAY(), "NO PRAZO", "VENCIDO" ) ) ) ) ) ),"N.A.") -> NO PRAZO | J12: =NR10.BAIXATENSAO[[#This Row],[TREINADO EM]]+NR10.BAIXATENSAO[[#This Row],[VALIDADE]] -> 46915 | K12: 40 | L12: APROVADO | M12: =VLOOKUP(NR10.BAIXATENSAO[[#This Row],[NOME]],'CADASTRO'!A:K,6,0) -> ATIVO
A13: EXTERNO | B13: EXXCELENCIA | C13: VINICIUS FERREIRA | D13: NR 10 - BAIXA E MEDIA TENSAO | E13: IGOR SANTOS SOUSA | F13: =VLOOKUP(NR10.BAIXATENSAO[[#This Row],[NOME]],'CADASTRO'!A:K,5,0) -> TECNICO AUTOMACAO | G13: 44252 | H13: 730 | I13: =IF(NR10.BAIXATENSAO[[#This Row],[SITUAÇÃO]]="ATIVO", IF(NR10.BAIXATENSAO[[#This Row],[CONDIÇÃO]]="N.A.", "N.A.", IF(NR10.BAIXATENSAO[[#This Row],[CONDIÇÃO]]="REPROVADO", "REPROVADO", IF(NR10.BAIXATENSAO[[#This Row],[CONDIÇÃO]]="RECICLADO", "HISTORICO", IF(NR10.BAIXATENSAO[[#This Row],[CONDIÇÃO]]="SEM REGISTRO", "SEM REGISTRO", IF(G344="01/01/1900", "SEM REGISTRO", IF((G13+H13)>TODAY(), "NO PRAZO", "VENCIDO" ) ) ) ) ) ),"N.A.") -> HISTORICO | J13: =NR10.BAIXATENSAO[[#This Row],[TREINADO EM]]+NR10.BAIXATENSAO[[#This Row],[VALIDADE]] -> 44982 | K13: 40 | L13: RECICLADO | M13: =VLOOKUP(NR10.BAIXATENSAO[[#This Row],[NOME]],'CADASTRO'!A:K,6,0) -> ATIVO
... A33: EXTERNO | B33: MERITUS | C33: LUIZ SANTOS | D33: NR 10 - BAIXA E MEDIA TENSAO | E33: WALLACE JOSE SILVA PEREIRA | F33: =VLOOKUP(NR10.BAIXATENSAO[[#This Row],[NOME]],'CADASTRO'!A:K,5,0) -> TECNICO ELETRONICO II | G33: 45631 | H33: 730 | I33: =IF(NR10.BAIXATENSAO[[#This Row],[SITUAÇÃO]]="ATIVO", IF(NR10.BAIXATENSAO[[#This Row],[CONDIÇÃO]]="N.A.", "N.A.", IF(NR10.BAIXATENSAO[[#This Row],[CONDIÇÃO]]="REPROVADO", "REPROVADO", IF(NR10.BAIXATENSAO[[#This Row],[CONDIÇÃO]]="RECICLADO", "HISTORICO", IF(NR10.BAIXATENSAO[[#This Row],[CONDIÇÃO]]="SEM REGISTRO", "SEM REGISTRO", IF(G364="01/01/1900", "SEM REGISTRO", IF((G33+H33)>TODAY(), "NO PRAZO", "VENCIDO" ) ) ) ) ) ),"N.A.") -> NO PRAZO | J33: =NR10.BAIXATENSAO[[#This Row],[TREINADO EM]]+NR10.BAIXATENSAO[[#This Row],[VALIDADE]] -> 46361 | K33: 40 | L33: APROVADO | M33: =VLOOKUP(NR10.BAIXATENSAO[[#This Row],[NOME]],'CADASTRO'!A:K,6,0) -> ATIVO

Sheet NR10 SEP
A1: ORIGEM | B1: FORNECEDOR | C1: INSTRUTOR | D1: TREINAMENTO | E1: NOME | F1: CARGO | G1: TREINADO EM | H1: VALIDADE | I1: STATUS | J1: VENCE EM | K1: CARGA HORARIA | L1: CONDIÇÃO | M1: SITUAÇÃO
A2: EXTERNO | B2: EXXCELENCIA | C2: DEYVID FRANKLIN | D2: NR 10 - SISTEMA ELETRICO DE POTENCIA | E2: ANGELO ROSEMBERG BELLO TEIXEIRA | F2: =VLOOKUP(NR10.SEP[[#This Row],[NOME]],'CADASTRO'!A:K,5,0) -> TECNICO ELETRONICO II | G2: 44873 | H2: 730 | I2: =IF(NR10.SEP[[#This Row],[SITUAÇÃO]]="ATIVO", IF(NR10.SEP[[#This Row],[CONDIÇÃO]]="N.A.", "N.A.", IF(NR10.SEP[[#This Row],[CONDIÇÃO]]="REPROVADO", "REPROVADO", IF(NR10.SEP[[#This Row],[CONDIÇÃO]]="RECICLADO", "HISTORICO", IF(NR10.SEP[[#This Row],[CONDIÇÃO]]="SEM REGISTRO", "SEM REGISTRO", IF(G338="01/01/1900", "SEM REGISTRO", IF((G2+H2)>TODAY(), "NO PRAZO", "VENCIDO" ) ) ) ) ) ),"N.A.") -> N.A. | J2: =NR10.SEP[[#This Row],[TREINADO EM]]+NR10.SEP[[#This Row],[VALIDADE]] -> 45603 | K2: 40 | L2: RECICLADO | M2: =VLOOKUP(NR10.SEP[[#This Row],[NOME]],'CADASTRO'!A:K,6,0) -> DESLIGADO
A3: EXTERNO | B3: MERITUS | C3: LUIZ MATTA | D3: NR 10 - SISTEMA ELETRICO DE POTENCIA | E3: ANGELO ROSEMBERG BELLO TEIXEIRA | F3: =VLOOKUP(NR10.SEP[[#This Row],[NOME]],'CADASTRO'!A:K,5,0) -> TECNICO ELETRONICO II | G3: 45512 | H3: 730 | I3: =IF(NR10.SEP[[#This Row],[SITUAÇÃO]]="ATIVO", IF(NR10.SEP[[#This Row],[CONDIÇÃO]]="N.A.", "N.A.", IF(NR10.SEP[[#This Row],[CONDIÇÃO]]="REPROVADO", "REPROVADO", IF(NR10.SEP[[#This Row],[CONDIÇÃO]]="RECICLADO", "HISTORICO", IF(NR10.SEP[[#This Row],[CONDIÇÃO]]="SEM REGISTRO", "SEM REGISTRO", IF(G339="01/01/1900", "SEM REGISTRO", IF((G3+H3)>TODAY(), "NO PRAZO", "VENCIDO" ) ) ) ) ) ),"N.A.") -> N.A. | J3: =NR10.SEP[[#This Row],[TREINADO EM]]+NR10.SEP[[#This Row],[VALIDADE]] -> 46242 | K3: 20 | L3: APROVADO | M3: =VLOOKUP(NR10.SEP[[#This Row],[NOME]],'CADASTRO'!A:K,6,0) -> DESLIGADO
A4: EXTERNO | B4: EXXCELENCIA | C4: DEYVID FRANKLIN | D4: NR 10 - SISTEMA ELETRICO DE POTENCIA | E4: FABIO DE SOUZA COELHO | F4: =VLOOKUP(NR10.SEP[[#This Row],[NOME]],'CADASTRO'!A:K,5,0) -> TECNICO ELETRONICO III | G4: 44873 | H4: 730 | I4: =IF(NR10.SEP[[#This Row],[SITUAÇÃO]]="ATIVO", IF(NR10.SEP[[#This Row],[CONDIÇÃO]]="N.A.", "N.A.", IF(NR10.SEP[[#This Row],[CONDIÇÃO]]="REPROVADO", "REPROVADO", IF(NR10.SEP[[#This Row],[CONDIÇÃO]]="RECICLADO", "HISTORICO", IF(NR10.SEP[[#This Row],[CONDIÇÃO]]="SEM REGISTRO", "SEM REGISTRO", IF(G340="01/01/1900", "SEM REGISTRO", IF((G4+H4)>TODAY(), "NO PRAZO", "VENCIDO" ) ) ) ) ) ),"N.A.") -> HISTORICO | J4: =NR10.SEP[[#This Row],[TREINADO EM]]+NR10.SEP[[#This Row],[VALIDADE]] -> 45603 | K4: 40 | L4: RECICLADO | M4: =VLOOKUP(NR10.SEP[[#This Row],[NOME]],'CADASTRO'!A:K,6,0) -> ATIVO
A5: EXTERNO | B5: MERITUS | C5: LUIZ MATTA | D5: NR 10 - SISTEMA ELETRICO DE POTENCIA | E5: FABIO DE SOUZA COELHO | F5: =VLOOKUP(NR10.SEP[[#This Row],[NOME]],'CADASTRO'!A:K,5,0) -> TECNICO ELETRONICO III | G5: 45512 | H5: 730 | I5: =IF(NR10.SEP[[#This Row],[SITUAÇÃO]]="ATIVO", IF(NR10.SEP[[#This Row],[CONDIÇÃO]]="N.A.", "N.A.", IF(NR10.SEP[[#This Row],[CONDIÇÃO]]="REPROVADO", "REPROVADO", IF(NR10.SEP[[#This Row],[CONDIÇÃO]]="RECICLADO", "HISTORICO", IF(NR10.SEP[[#This Row],[CONDIÇÃO]]="SEM REGISTRO", "SEM REGISTRO", IF(G341="01/01/1900", "SEM REGISTRO", IF((G5+H5)>TODAY(), "NO PRAZO", "VENCIDO" ) ) ) ) ) ),"N.A.") -> HISTORICO | J5: =NR10.SEP[[#This Row],[TREINADO EM]]+NR10.SEP[[#This Row],[VALIDADE]] -> 46242 | K5: 20 | L5: RECICLADO | M5: =VLOOKUP(NR10.SEP[[#This Row],[NOME]],'CADASTRO'!A:K,6,0) -> ATIVO
